Workbook

Sheet 2026 Ιανουάριος
A1: ΑΝΑΛΥΣΗ ΑΠΟΤΕΛΕΣΜΑΤΟΣ ΜΗΝΟΣ
A2: 1 | C2: ΑΝΑΛΥΣΗ ΕΤΟΥΣ 2026 | D2: =[1]ΑΝΤΙΣΤΟΙΧΙΣΗ!$F$32 | H2: =[1]ΑΝΤΙΣΤΟΙΧΙΣΗ!$F$35 | L2: =[1]ΑΝΤΙΣΤΟΙΧΙΣΗ!$F$68 | P2: =[1]ΑΝΤΙΣΤΟΙΧΙΣΗ!$F$100
A3: 2 | C3: ΠΕΡΙΟΔΟΣ | D3: =[1]ΑΝΤΙΣΤΟΙΧΙΣΗ!$F$106 | G3: =[1]ΑΝΤΙΣΤΟΙΧΙΣΗ!$D$34 | H3: =[1]ΑΝΤΙΣΤΟΙΧΙΣΗ!$F$106 | K3: =[1]ΑΝΤΙΣΤΟΙΧΙΣΗ!$D$34 | L3: =[1]ΑΝΤΙΣΤΟΙΧΙΣΗ!$F$120 | O3: =[1]ΑΝΤΙΣΤΟΙΧΙΣΗ!$D$33
A4: 3 | B4: Α | C4: Κατηγορία Εσόδου | D4: Ποσά | E4: % Εσοδο Γραμμής/Σύν.Εσ.Μηνός | F4: Προοδευτικό Σύνολο Εσόδων έως σήμερα | G4: % Προοδ.Σύνολο Κατηγ. Εσ. /Προοδ.Σύν.Εσ. Έως σήμερα | H4: Εσοδο Μηνός | I4: % Εσοδο Γραμμής /Σύν.Εσ.Μηνός | J4: Προοδευτικό έως σήμερα | K4: % Προοδ.Σύνολο Κατηγ. Εσ. /Προοδ.Σύν.Εσ. Έως σήμερα | L4: Εσοδο Μηνός 2024 | M4: % Εσοδο Γραμμής/Σύν.Εσ.Μηνός | N4: Προοδευτικό Σύνολο Εσόδων έως Τρέχοντα μήνα | O4: % Προοδ.Σύνολο Κατηγ. Εσ. /Προοδ.Σύν.Εσ. Έως σήμερα | P4: Προοδ. Διαφορά Συν. Πραγμ.Τρ. Έτους - Αντιστ. Προοδ. Σύν. Πραγμ. Προηγ. Έτους | Q4: % Προοδ. Διαφορά Κατηγ. Εσ. / Προοδ.Σύν.Προυπ. Εσ. Τρέχοντος Έτους
A5: 4 | C5: Λογιστικό Αποτέλεσμα μηνός | D5: =D7-D6 | F5: =F7-F6 | H5: =H159-H6 | J5: =J159-J6 | L5: =L7-L6 | N5: =N7-N6 | P5: =P159-P6
A6: 5 | C6: Σύνολο Εξόδων Μηνός | D6: =D43+D84+D116 | F6: =F78+F111+F157 | H6: =H38-H43-H84 | J6: =J38-J43-J84 | L6: =L43+L84+L116 | N6: =N78+N111+N157 | P6: =P38-P43-P84
A7: 6 | B7: Α/Α | C7: Σύνολο Εσόδων Μηνός | D7: =SUM(D8:D31) | F7: =SUM(F8:F31) | H7: =SUM(H8:H31) | J7: =SUM(J8:J31) | L7: =SUM(L8:L31) | N7: =L7 | P7: =SUM(P8:P31)
A8: 7 | B8: 1 | C8: =[1]ΑΝΤΙΣΤΟΙΧΙΣΗ!F187 | D8: ='[1]2026_ΕΣΟΔΑ'!C2 | E8: =D8/$D$7 | F8: =D8 | G8: =F8/$F$7 | H8: 0 | I8: =H8/$H$7 | J8: =H8 | K8: =J8/$J$7 | L8: ='[1]2024_60-69 ΕΞΟΔΑ+ΟΜ 2'!C114 | M8: =L8/$L$7 | N8: =L8 | O8: =N8/$N$7 | P8: =F8-N8 | Q8: =P8/J8
A9: 8 | B9: 2 | C9: =[1]ΑΝΤΙΣΤΟΙΧΙΣΗ!F188 | D9: ='[1]2026_ΕΣΟΔΑ'!C3 | E9: =D9/$D$7 | F9: =D9 | G9: =F9/$F$7 | I9: =H9/$H$7 | J9: =H9 | K9: =J9/$J$7 | L9: ='[1]2024_60-69 ΕΞΟΔΑ+ΟΜ 2'!C115 | M9: =L9/$L$7 | N9: =L9 | O9: =N9/$N$7 | P9: =F9-N9 | Q9: =P9/J9
A10: 9 | B10: 3 | C10: =[1]ΑΝΤΙΣΤΟΙΧΙΣΗ!F189 | D10: ='[1]2026_ΕΣΟΔΑ'!C4 | E10: =D10/$D$7 | F10: =D10 | G10: =F10/$F$7 | I10: =H10/$H$7 | J10: =H10 | K10: =J10/$J$7 | L10: ='[1]2024_60-69 ΕΞΟΔΑ+ΟΜ 2'!C116 | M10: =L10/$L$7 | N10: =L10 | O10: =N10/$N$7 | P10: =F10-N10 | Q10: =P10/J10
A11: 10 | B11: 4 | C11: =[1]ΑΝΤΙΣΤΟΙΧΙΣΗ!F190 | D11: ='[1]2026_ΕΣΟΔΑ'!C5 | E11: =D11/$D$7 | F11: =D11 | G11: =F11/$F$7 | I11: =H11/$H$7 | J11: =H11 | K11: =J11/$J$7 | L11: ='[1]2024_60-69 ΕΞΟΔΑ+ΟΜ 2'!C117 | M11: =L11/$L$7 | N11: =L11 | O11: =N11/$N$7 | P11: =F11-N11 | Q11: =P11/J11
A12: 11 | B12: 5 | C12: =[1]ΑΝΤΙΣΤΟΙΧΙΣΗ!F191 | D12: ='[1]2026_ΕΣΟΔΑ'!C6 | E12: =D12/$D$7 | F12: =D12 | G12: =F12/$F$7 | I12: =H12/$H$7 | J12: =H12 | K12: =J12/$J$7 | L12: ='[1]2024_60-69 ΕΞΟΔΑ+ΟΜ 2'!C118 | M12: =L12/$L$7 | N12: =L12 | O12: =N12/$N$7 | P12: =F12-N12 | Q12: =P12/J12
A13: 12 | B13: 6 | C13: =[1]ΑΝΤΙΣΤΟΙΧΙΣΗ!F192 | D13: ='[1]2026_ΕΣΟΔΑ'!C7 | E13: =D13/$D$7 | F13: =D13 | G13: =F13/$F$7 | I13: =H13/$H$7 | J13: =H13 | K13: =J13/$J$7 | L13: ='[1]2024_60-69 ΕΞΟΔΑ+ΟΜ 2'!C119 | M13: =L13/$L$7 | N13: =L13 | O13: =N13/$N$7 | P13: =F13-N13 | Q13: =P13/J13
A14: 13 | B14: 7 | C14: =[1]ΑΝΤΙΣΤΟΙΧΙΣΗ!F193 | D14: ='[1]2026_ΕΣΟΔΑ'!C8 | E14: =D14/$D$7 | F14: =D14 | G14: =F14/$F$7 | I14: =H14/$H$7 | J14: =H14 | K14: =J14/$J$7 | L14: ='[1]2024_60-69 ΕΞΟΔΑ+ΟΜ 2'!C120 | M14: =L14/$L$7 | N14: =L14 | O14: =N14/$N$7 | P14: =F14-N14 | Q14: =P14/J14
A15: 14 | B15: 8 | C15: =[1]ΑΝΤΙΣΤΟΙΧΙΣΗ!F194 | D15: ='[1]2026_ΕΣΟΔΑ'!C9 | E15: =D15/$D$7 | F15: =D15 | G15: =F15/$F$7 | I15: =H15/$H$7 | J15: =H15 | K15: =J15/$J$7 | L15: ='[1]2024_60-69 ΕΞΟΔΑ+ΟΜ 2'!C121 | M15: =L15/$L$7 | N15: =L15 | O15: =N15/$N$7 | P15: =F15-N15 | Q15: =P15/J15
A16: 15 | B16: 9 | C16: =[1]ΑΝΤΙΣΤΟΙΧΙΣΗ!F195 | D16: ='[1]2026_ΕΣΟΔΑ'!C10 | E16: =D16/$D$7 | F16: =D16 | G16: =F16/$F$7 | I16: =H16/$H$7 | J16: =H16 | K16: =J16/$J$7 | L16: ='[1]2024_60-69 ΕΞΟΔΑ+ΟΜ 2'!C122 | M16: =L16/$L$7 | N16: =L16 | O16: =N16/$N$7 | P16: =F16-N16 | Q16: =P16/J16
A17: 16 | B17: 10 | C17: =[1]ΑΝΤΙΣΤΟΙΧΙΣΗ!F196 | D17: ='[1]2026_ΕΣΟΔΑ'!C11 | E17: =D17/$D$7 | F17: =D17 | G17: =F17/$F$7 | I17: =H17/$H$7 | J17: =H17 | K17: =J17/$J$7 | L17: ='[1]2024_60-69 ΕΞΟΔΑ+ΟΜ 2'!C123 | M17: =L17/$L$7 | N17: =L17 | O17: =N17/$N$7 | P17: =F17-N17 | Q17: =P17/J17
A18: 17 | B18: 11 | C18: =[1]ΑΝΤΙΣΤΟΙΧΙΣΗ!F197 | D18: ='[1]2026_ΕΣΟΔΑ'!C12 | E18: =D18/$D$7 | F18: =D18 | G18: =F18/$F$7 | I18: =H18/$H$7 | J18: =H18 | K18: =J18/$J$7 | L18: ='[1]2024_60-69 ΕΞΟΔΑ+ΟΜ 2'!C124 | M18: =L18/$L$7 | N18: =L18 | O18: =N18/$N$7 | P18: =F18-N18 | Q18: =P18/J18
A19: 18 | B19: 12 | C19: =[1]ΑΝΤΙΣΤΟΙΧΙΣΗ!F198 | D19: ='[1]2026_ΕΣΟΔΑ'!C13 | E19: =D19/$D$7 | F19: =D19 | G19: =F19/$F$7 | I19: =H19/$H$7 | J19: =H19 | K19: =J19/$J$7 | L19: ='[1]2024_60-69 ΕΞΟΔΑ+ΟΜ 2'!C125 | M19: =L19/$L$7 | N19: =L19 | O19: =N19/$N$7 | P19: =F19-N19 | Q19: =P19/J19
A20: 19 | B20: 13 | C20: =[1]ΑΝΤΙΣΤΟΙΧΙΣΗ!F199 | D20: ='[1]2026_ΕΣΟΔΑ'!C14 | E20: =D20/$D$7 | F20: =D20 | G20: =F20/$F$7 | I20: =H20/$H$7 | J20: =H20 | K20: =J20/$J$7 | L20: ='[1]2024_60-69 ΕΞΟΔΑ+ΟΜ 2'!C126 | M20: =L20/$L$7 | N20: =L20 | O20: =N20/$N$7 | P20: =F20-N20 | Q20: =P20/J20
... A23: 22 | B23: 16 | C23: =[1]ΑΝΤΙΣΤΟΙΧΙΣΗ!F202 | D23: ='[1]2026_ΕΣΟΔΑ'!C17 | E23: =D23/$D$7 | F23: =D23 | G23: =F23/$F$7 | I23: =H23/$H$7 | J23: =H23 | K23: =J23/$J$7 | L23: ='[1]2024_60-69 ΕΞΟΔΑ+ΟΜ 2'!C129 | M23: =L23/$L$7 | N23: =L23 | O23: =N23/$N$7 | P23: =F23-N23 | Q23: =P23/J23
A24: 23 | B24: 17 | C24: =[1]ΑΝΤΙΣΤΟΙΧΙΣΗ!F203 | D24: ='[1]2026_ΕΣΟΔΑ'!C18 | E24: =D24/$D$7 | F24: =D24 | G24: =F24/$F$7 | H24: =[1]ΠΡΟΥΠΟΛΟΓΙΣΜΟΣ_ΕΣΟΔΑ!E225 | I24: =H24/$H$7 | J24: =H24 | K24: =J24/$J$7 | L24: ='[1]2024_60-69 ΕΞΟΔΑ+ΟΜ 2'!C130 | M24: =L24/$L$7 | N24: =L24 | O24: =N24/$N$7 | P24: =F24-N24 | Q24: =F24/J24
A25: 24 | B25: 18 | C25: =[1]ΑΝΤΙΣΤΟΙΧΙΣΗ!F204 | D25: ='[1]2026_ΕΣΟΔΑ'!C19 | E25: =D25/$D$7 | F25: =D25 | G25: =F25/$F$7 | I25: =H25/$H$7 | J25: =H25 | K25: =J25/$J$7 | L25: ='[1]2024_60-69 ΕΞΟΔΑ+ΟΜ 2'!C131 | M25: =L25/$L$7 | N25: =L25 | O25: =N25/$N$7 | P25: =F25-N25 | Q25: =P25/J25
A26: 25 | B26: 19 | C26: =[1]ΑΝΤΙΣΤΟΙΧΙΣΗ!F205 | D26: ='[1]2026_ΕΣΟΔΑ'!C20 | E26: =D26/$D$7 | F26: =D26 | G26: =F26/$F$7 | I26: =H26/$H$7 | J26: =H26 | K26: =J26/$J$7 | L26: ='[1]2024_60-69 ΕΞΟΔΑ+ΟΜ 2'!C132 | M26: =L26/$L$7 | N26: =L26 | O26: =N26/$N$7 | P26: =F26-N26 | Q26: =P26/J26
A27: 26 | B27: 20 | C27: =[1]ΑΝΤΙΣΤΟΙΧΙΣΗ!F206 | D27: ='[1]2026_ΕΣΟΔΑ'!C21 | E27: =D27/$D$7 | F27: =D27 | G27: =F27/$F$7 | I27: =H27/$H$7 | J27: =H27 | K27: =J27/$J$7 | L27: ='[1]2024_60-69 ΕΞΟΔΑ+ΟΜ 2'!C133 | M27: =L27/$L$7 | N27: =L27 | O27: =N27/$N$7 | P27: =F27-N27 | Q27: =P27/J27
A28: 27 | B28: 21 | C28: =[1]ΑΝΤΙΣΤΟΙΧΙΣΗ!F207 | D28: ='[1]2026_ΕΣΟΔΑ'!C22 | E28: =D28/$D$7 | F28: =D28 | G28: =F28/$F$7 | I28: =H28/$H$7 | J28: =H28 | K28: =J28/$J$7 | L28: ='[1]2024_60-69 ΕΞΟΔΑ+ΟΜ 2'!C134 | M28: =L28/$L$7 | N28: =L28 | O28: =N28/$N$7 | P28: =F28-N28 | Q28: =P28/J28
A29: 28 | B29: 22 | C29: =[1]ΑΝΤΙΣΤΟΙΧΙΣΗ!F208 | D29: ='[1]2026_ΕΣΟΔΑ'!C23 | E29: =D29/$D$7 | F29: =D29 | G29: =F29/$F$7 | I29: =H29/$H$7 | J29: =H29 | K29: =J29/$J$7 | L29: ='[1]2024_60-69 ΕΞΟΔΑ+ΟΜ 2'!C135 | M29: =L29/$L$7 | N29: =L29 | O29: =N29/$N$7 | P29: =F29-N29 | Q29: =P29/J29
A30: 29 | B30: 23 | C30: =[1]ΑΝΤΙΣΤΟΙΧΙΣΗ!F209 | D30: ='[1]2026_ΕΣΟΔΑ'!C24 | E30: =D30/$D$7 | F30: =D30 | G30: =F30/$F$7 | I30: =H30/$H$7 | J30: =H30 | K30: =J30/$J$7 | L30: ='[1]2024_60-69 ΕΞΟΔΑ+ΟΜ 2'!C136 | M30: =L30/$L$7 | N30: =L30 | O30: =N30/$N$7 | P30: =F30-N30 | Q30: =P30/J30
A31: 30 | B31: 24 | C31: =[1]ΑΝΤΙΣΤΟΙΧΙΣΗ!F210 | D31: ='[1]2026_ΕΣΟΔΑ'!C25 | E31: =D31/$D$7 | F31: =D31 | G31: =F31/$F$7 | I31: =H31/$H$7 | J31: =H31 | K31: =J31/$J$7 | L31: ='[1]2024_60-69 ΕΞΟΔΑ+ΟΜ 2'!C137 | M31: =L31/$L$7 | N31: =L31 | O31: =N31/$N$7 | P31: =F31-N31 | Q31: =P31/J31
A32: 31 | B32: 25 | C32: =[1]ΑΝΤΙΣΤΟΙΧΙΣΗ!F211 | D32: ='[1]2026_ΕΣΟΔΑ'!C26 | E32: =D32/$D$7 | F32: =D32 | G32: =F32/$F$7 | I32: =H32/$H$7 | J32: =H32 | K32: =J32/$J$7 | L32: ='[1]2024_60-69 ΕΞΟΔΑ+ΟΜ 2'!C138 | M32: =L32/$L$7 | N32: =L32 | O32: =N32/$N$7 | P32: =F32-N32 | Q32: =P32/J32
A33: 32 | B33: 26 | C33: =[1]ΑΝΤΙΣΤΟΙΧΙΣΗ!F212 | D33: ='[1]2026_ΕΣΟΔΑ'!C27 | E33: =D33/$D$7 | F33: =D33 | G33: =F33/$F$7 | I33: =H33/$H$7 | J33: =H33 | K33: =J33/$J$7 | L33: ='[1]2024_60-69 ΕΞΟΔΑ+ΟΜ 2'!C139 | M33: =L33/$L$7 | N33: =L33 | O33: =N33/$N$7 | P33: =F33-N33 | Q33: =P33/J33
A34: 33 | B34: 27 | C34: =[1]ΑΝΤΙΣΤΟΙΧΙΣΗ!F213 | D34: ='[1]2026_ΕΣΟΔΑ'!C28 | E34: =D34/$D$7 | F34: =D34 | G34: =F34/$F$7 | I34: =H34/$H$7 | J34: =H34 | K34: =J34/$J$7 | L34: ='[1]2024_60-69 ΕΞΟΔΑ+ΟΜ 2'!C140 | M34: =L34/$L$7 | N34: =L34 | O34: =N34/$N$7 | P34: =F34-N34 | Q34: =P34/J34
A35: 34 | B35: 28 | C35: =[1]ΑΝΤΙΣΤΟΙΧΙΣΗ!F214 | D35: ='[1]2026_ΕΣΟΔΑ'!C29 | E35: =D35/$D$7 | F35: =D35 | G35: =F35/$F$7 | I35: =H35/$H$7 | J35: =H35 | K35: =J35/$J$7 | L35: ='[1]2024_60-69 ΕΞΟΔΑ+ΟΜ 2'!C141 | M35: =L35/$L$7 | N35: =L35 | O35: =N35/$N$7 | P35: =F35-N35 | Q35: =P35/J35
A36: 35 | B36: 29 | C36: =[1]ΑΝΤΙΣΤΟΙΧΙΣΗ!F215 | D36: ='[1]2026_ΕΣΟΔΑ'!C30 | E36: =D36/$D$7 | F36: =D36 | G36: =F36/$F$7 | I36: =H36/$H$7 | J36: =H36 | K36: =J36/$J$7 | L36: ='[1]2024_60-69 ΕΞΟΔΑ+ΟΜ 2'!C142 | M36: =L36/$L$7 | N36: =L36 | O36: =N36/$N$7 | P36: =F36-N36 | Q36: =P36/J36
A37: 36 | B37: 30 | C37: =[1]ΑΝΤΙΣΤΟΙΧΙΣΗ!F216 | D37: ='[1]2026_ΕΣΟΔΑ'!C31 | E37: =D37/$D$7 | F37: =D37 | G37: =F37/$F$7 | I37: =H37/$H$7 | J37: =H37 | K37: =J37/$J$7 | L37: ='[1]2024_60-69 ΕΞΟΔΑ+ΟΜ 2'!C143 | M37: =L37/$L$7 | N37: =L37 | O37: =N37/$N$7 | P37: =F37-N37 | Q37: =P37/J37
A38: 37 | C38: ΣΥΝΟΛΟ ΕΣΟΔΩΝ ΜΗΝΟΣ | D38: ='[1]2026_ΕΣΟΔΑ'!C32 | F38: ='[1]2026_ΕΣΟΔΑ'!C34 | H38: =SUM(H8:H30) | J38: =SUM(J8:J30) | L38: =SUM(L8:L31) | N38: =SUM(N8:N31) | P38: =SUM(P8:P30)
A39: 38 | C39: Ελεγχος Ορθότητας ( πρέπει να είναι 0) | D39: =D7-D38 | F39: =F7-F38 | H39: =H7-H38 | J39: =J7-J38 | L39: =L7-L38 | N39: =N7-N38 | P39: =P7-P38
A40: 39 | C40: ΑΝΑΛΥΣΗ ΕΤΟΥΣ 2026 | D40: =[1]ΑΝΤΙΣΤΟΙΧΙΣΗ!$F$32 | H40: =[1]ΑΝΤΙΣΤΟΙΧΙΣΗ!$F$35 | L40: =[1]ΑΝΤΙΣΤΟΙΧΙΣΗ!$F$68 | P40: =[1]ΑΝΤΙΣΤΟΙΧΙΣΗ!$F$100
A41: 40 | C41: ΠΕΡΙΟΔΟΣ | D41: =[1]ΑΝΤΙΣΤΟΙΧΙΣΗ!$F$106 | G41: =[1]ΑΝΤΙΣΤΟΙΧΙΣΗ!$D$34 | H41: =[1]ΑΝΤΙΣΤΟΙΧΙΣΗ!$F$106 | K41: =[1]ΑΝΤΙΣΤΟΙΧΙΣΗ!$D$34 | L41: =[1]ΑΝΤΙΣΤΟΙΧΙΣΗ!$F$120 | O41: =[1]ΑΝΤΙΣΤΟΙΧΙΣΗ!$D$33
A42: 41 | B42: Β | C42: ΚΑΤΗΓΟΡΙΑ ΕΞΟΔΟΥ | D42: Ποσά | E42: % Εξοδο Γραμμής /Σύν.Εξόδων μηνός | F42: Προοδ Σύν. Κατηγ. Εξόδων έως Σήμερα | G42: % Προοδ. Σύνολο Κατηγ. Εξ./ Προοδ. Σύνολο Εξόδων Έως σήμερα | H42: Αμ. Κόστ. Υπηρ. Μηνός | I42: % Εξοδο Γραμμής /Σύν.Εξόδων μηνός | J42: Προοδ Σύν. Κατηγ. Εξόδων έως Σήμερα | K42: % Προοδ. Σύνολο Κατηγ. Εξ./ Προοδ. Σύνολο Εξόδων Έως σήμερα | L42: Αμ. Κόστ. Υπηρ. Μηνός | M42: % Κατηγ.Εξ/Σύν.Αμ.Κο.Υπ.μηνός | N42: Προοδ Σύν. Κατηγ. Εξ έως Σήμερα | O42: % Προοδ. Σύν. Κατηγ. Εξ/ Προοδ. Σύνολο Εξόδων | P42: Προοδ. Διαφορά με Προηγ. Έτος ( Τρέχον Έτος - Προηγ. Έτος) | Q42: % Προοδ.Σύν Κατηγ. Εξ. Πρ. Έτους / Προοδ.Σύν.Εξ. Τρέχοντος Έτους
...

Sheet 2026 Φεβρουάριος
A1: ΑΝΑΛΥΣΗ ΑΠΟΤΕΛΕΣΜΑΤΟΣ ΜΗΝΟΣ
A2: 1 | C2: ΑΝΑΛΥΣΗ ΕΤΟΥΣ 2026 | D2: =[1]ΑΝΤΙΣΤΟΙΧΙΣΗ!$F$32 | H2: =[1]ΑΝΤΙΣΤΟΙΧΙΣΗ!$F$35 | L2: =[1]ΑΝΤΙΣΤΟΙΧΙΣΗ!$F$68 | P2: =[1]ΑΝΤΙΣΤΟΙΧΙΣΗ!$F$100
A3: 2 | C3: ΕΙΔΟΣ ΕΣΟΔΩΝ | D3: =[1]ΑΝΤΙΣΤΟΙΧΙΣΗ!$F$107 | G3: =[1]ΑΝΤΙΣΤΟΙΧΙΣΗ!$D$34 | H3: =[1]ΑΝΤΙΣΤΟΙΧΙΣΗ!$F$107 | K3: =[1]ΑΝΤΙΣΤΟΙΧΙΣΗ!$D$34 | L3: =[1]ΑΝΤΙΣΤΟΙΧΙΣΗ!$F$121 | O3: =[1]ΑΝΤΙΣΤΟΙΧΙΣΗ!$D$33
A4: 3 | B4: Α | C4: Κατηγορία Εσόδου | D4: Εσοδο Μηνός | E4: % Εσοδο Γραμμής/Σύν.Εσ.Μηνός | F4: Προοδευτικό Σύνολο Εσόδων έως σήμερα | G4: % Προοδ.Σύνολο Κατηγ. Εσ. /Προοδ.Σύν.Εσ. Έως σήμερα | H4: Εσοδο Μηνός | I4: % Εσοδο Γραμμής /Σύν.Εσ.Μηνός | J4: Προοδευτικό έως σήμερα | K4: % Προοδ.Σύνολο Κατηγ. Εσ. /Προοδ.Σύν.Εσ. Έως σήμερα | L4: Εσοδο Μηνός 2024 | M4: % Εσοδο Γραμμής/Σύν.Εσ.Μηνός | N4: Προοδευτικό Σύνολο Εσόδων έως Τρέχοντα μήνα | O4: % Προοδ.Σύνολο Κατηγ. Εσ. /Προοδ.Σύν.Εσ. Έως σήμερα | P4: Προοδ. Διαφορά Συν. Πραγμ.Τρ. Έτους - Αντιστ. Προοδ. Σύν. Πραγμ. Προηγ. Έτους | Q4: % Προοδ. Διαφορά Κατηγ. Εσ. / Προοδ.Σύν.Προυπ. Εσ. Τρέχοντος Έτους
A5: 4 | C5: Λογιστικό Αποτέλεσμα μηνός | D5: =D7-D6 | F5: =F7-F6 | H5: =H159-H6 | J5: =J159-J6 | L5: =L7-L6 | N5: =N7-N6 | P5: =P159-P6
A6: 5 | C6: Σύνολο Εξόδων Μηνός | D6: =D43+D84+D116 | F6: =F78+F111+F157 | H6: =H38-H43-H84 | J6: =J38-J43-J84 | L6: =L43+L84+L116 | N6: =N78+N111+N157 | P6: =P38-P43-P84
A7: 6 | B7: Α/Α | C7: Σύνολο Εσόδων Μηνός | D7: =SUM(D8:D37) | F7: =SUM(F8:F37) | H7: =SUM(H8:H31) | J7: =SUM(J8:J31) | L7: =SUM(L8:L31) | N7: =L7+'[1]2026 Ιανουάριος'!N7 | P7: =SUM(P8:P31)
A8: 7 | B8: 1 | C8: =[1]ΑΝΤΙΣΤΟΙΧΙΣΗ!F187 | D8: ='[1]2026_ΕΣΟΔΑ'!D2 | E8: =D8/$D$7 | F8: ='[1]2026 Ιανουάριος'!F8+'2026 Φεβρουάριος'!D8 | G8: =F8/$F$7 | I8: =H8/$H$7 | J8: =H8+'[1]2026 Ιανουάριος'!J8 | K8: =J8/$J$7 | L8: ='[1]2024_60-69 ΕΞΟΔΑ+ΟΜ 2'!D114 | M8: =L8/$L$7 | N8: =L8+'[1]2026 Ιανουάριος'!N8 | O8: =N8/$N$7 | P8: =F8-N8 | Q8: =N8/F8
A9: 8 | B9: 2 | C9: =[1]ΑΝΤΙΣΤΟΙΧΙΣΗ!F188 | D9: ='[1]2026_ΕΣΟΔΑ'!D3 | E9: =D9/$D$7 | F9: ='[1]2026 Ιανουάριος'!F9+'2026 Φεβρουάριος'!D9 | G9: =F9/$F$7 | I9: =H9/$H$7 | J9: =H9+'[1]2026 Ιανουάριος'!J9 | K9: =J9/$J$7 | L9: ='[1]2024_60-69 ΕΞΟΔΑ+ΟΜ 2'!D115 | M9: =L9/$L$7 | N9: =L9+'[1]2026 Ιανουάριος'!N9 | O9: =N9/$N$7 | P9: =F9-N9 | Q9: =N9/F9
A10: 9 | B10: 3 | C10: =[1]ΑΝΤΙΣΤΟΙΧΙΣΗ!F189 | D10: ='[1]2026_ΕΣΟΔΑ'!D4 | E10: =D10/$D$7 | F10: ='[1]2026 Ιανουάριος'!F10+'2026 Φεβρουάριος'!D10 | G10: =F10/$F$7 | I10: =H10/$H$7 | J10: =H10+'[1]2026 Ιανουάριος'!J10 | K10: =J10/$J$7 | L10: ='[1]2024_60-69 ΕΞΟΔΑ+ΟΜ 2'!D116 | M10: =L10/$L$7 | N10: =L10+'[1]2026 Ιανουάριος'!N10 | O10: =N10/$N$7 | P10: =F10-N10 | Q10: =N10/F10
A11: 10 | B11: 4 | C11: =[1]ΑΝΤΙΣΤΟΙΧΙΣΗ!F190 | D11: ='[1]2026_ΕΣΟΔΑ'!D5 | E11: =D11/$D$7 | F11: ='[1]2026 Ιανουάριος'!F11+'2026 Φεβρουάριος'!D11 | G11: =F11/$F$7 | I11: =H11/$H$7 | J11: =H11+'[1]2026 Ιανουάριος'!J11 | K11: =J11/$J$7 | L11: ='[1]2024_60-69 ΕΞΟΔΑ+ΟΜ 2'!D117 | M11: =L11/$L$7 | N11: =L11+'[1]2026 Ιανουάριος'!N11 | O11: =N11/$N$7 | P11: =F11-N11 | Q11: =N11/F11
A12: 11 | B12: 5 | C12: =[1]ΑΝΤΙΣΤΟΙΧΙΣΗ!F191 | D12: ='[1]2026_ΕΣΟΔΑ'!D6 | E12: =D12/$D$7 | F12: ='[1]2026 Ιανουάριος'!F12+'2026 Φεβρουάριος'!D12 | G12: =F12/$F$7 | I12: =H12/$H$7 | J12: =H12+'[1]2026 Ιανουάριος'!J12 | K12: =J12/$J$7 | L12: ='[1]2024_60-69 ΕΞΟΔΑ+ΟΜ 2'!D118 | M12: =L12/$L$7 | N12: =L12+'[1]2026 Ιανουάριος'!N12 | O12: =N12/$N$7 | P12: =F12-N12 | Q12: =N12/F12
A13: 12 | B13: 6 | C13: =[1]ΑΝΤΙΣΤΟΙΧΙΣΗ!F192 | D13: ='[1]2026_ΕΣΟΔΑ'!D7 | E13: =D13/$D$7 | F13: ='[1]2026 Ιανουάριος'!F13+'2026 Φεβρουάριος'!D13 | G13: =F13/$F$7 | I13: =H13/$H$7 | J13: =H13+'[1]2026 Ιανουάριος'!J13 | K13: =J13/$J$7 | L13: ='[1]2024_60-69 ΕΞΟΔΑ+ΟΜ 2'!D119 | M13: =L13/$L$7 | N13: =L13+'[1]2026 Ιανουάριος'!N13 | O13: =N13/$N$7 | P13: =F13-N13 | Q13: =N13/F13
A14: 13 | B14: 7 | C14: =[1]ΑΝΤΙΣΤΟΙΧΙΣΗ!F193 | D14: ='[1]2026_ΕΣΟΔΑ'!D8 | E14: =D14/$D$7 | F14: ='[1]2026 Ιανουάριος'!F14+'2026 Φεβρουάριος'!D14 | G14: =F14/$F$7 | I14: =H14/$H$7 | J14: =H14+'[1]2026 Ιανουάριος'!J14 | K14: =J14/$J$7 | L14: ='[1]2024_60-69 ΕΞΟΔΑ+ΟΜ 2'!D120 | M14: =L14/$L$7 | N14: =L14+'[1]2026 Ιανουάριος'!N14 | O14: =N14/$N$7 | P14: =F14-N14 | Q14: =N14/F14
A15: 14 | B15: 8 | C15: =[1]ΑΝΤΙΣΤΟΙΧΙΣΗ!F194 | D15: ='[1]2026_ΕΣΟΔΑ'!D9 | E15: =D15/$D$7 | F15: ='[1]2026 Ιανουάριος'!F15+'2026 Φεβρουάριος'!D15 | G15: =F15/$F$7 | I15: =H15/$H$7 | J15: =H15+'[1]2026 Ιανουάριος'!J15 | K15: =J15/$J$7 | L15: ='[1]2024_60-69 ΕΞΟΔΑ+ΟΜ 2'!D121 | M15: =L15/$L$7 | N15: =L15+'[1]2026 Ιανουάριος'!N15 | O15: =N15/$N$7 | P15: =F15-N15 | Q15: =N15/F15
A16: 15 | B16: 9 | C16: =[1]ΑΝΤΙΣΤΟΙΧΙΣΗ!F195 | D16: ='[1]2026_ΕΣΟΔΑ'!D10 | E16: =D16/$D$7 | F16: ='[1]2026 Ιανουάριος'!F16+'2026 Φεβρουάριος'!D16 | G16: =F16/$F$7 | I16: =H16/$H$7 | J16: =H16+'[1]2026 Ιανουάριος'!J16 | K16: =J16/$J$7 | L16: ='[1]2024_60-69 ΕΞΟΔΑ+ΟΜ 2'!D122 | M16: =L16/$L$7 | N16: =L16+'[1]2026 Ιανουάριος'!N16 | O16: =N16/$N$7 | P16: =F16-N16 | Q16: =N16/F16
A17: 16 | B17: 10 | C17: =[1]ΑΝΤΙΣΤΟΙΧΙΣΗ!F196 | D17: ='[1]2026_ΕΣΟΔΑ'!D11 | E17: =D17/$D$7 | F17: ='[1]2026 Ιανουάριος'!F17+'2026 Φεβρουάριος'!D17 | G17: =F17/$F$7 | I17: =H17/$H$7 | J17: =H17+'[1]2026 Ιανουάριος'!J17 | K17: =J17/$J$7 | L17: ='[1]2024_60-69 ΕΞΟΔΑ+ΟΜ 2'!D123 | M17: =L17/$L$7 | N17: =L17+'[1]2026 Ιανουάριος'!N17 | O17: =N17/$N$7 | P17: =F17-N17 | Q17: =N17/F17
A18: 17 | B18: 11 | C18: =[1]ΑΝΤΙΣΤΟΙΧΙΣΗ!F197 | D18: ='[1]2026_ΕΣΟΔΑ'!D12 | E18: =D18/$D$7 | F18: ='[1]2026 Ιανουάριος'!F18+'2026 Φεβρουάριος'!D18 | G18: =F18/$F$7 | I18: =H18/$H$7 | J18: =H18+'[1]2026 Ιανουάριος'!J18 | K18: =J18/$J$7 | L18: ='[1]2024_60-69 ΕΞΟΔΑ+ΟΜ 2'!D124 | M18: =L18/$L$7 | N18: =L18+'[1]2026 Ιανουάριος'!N18 | O18: =N18/$N$7 | P18: =F18-N18 | Q18: =N18/F18
A19: 18 | B19: 12 | C19: =[1]ΑΝΤΙΣΤΟΙΧΙΣΗ!F198 | D19: ='[1]2026_ΕΣΟΔΑ'!D13 | E19: =D19/$D$7 | F19: ='[1]2026 Ιανουάριος'!F19+'2026 Φεβρουάριος'!D19 | G19: =F19/$F$7 | I19: =H19/$H$7 | J19: =H19+'[1]2026 Ιανουάριος'!J19 | K19: =J19/$J$7 | L19: ='[1]2024_60-69 ΕΞΟΔΑ+ΟΜ 2'!D125 | M19: =L19/$L$7 | N19: =L19+'[1]2026 Ιανουάριος'!N19 | O19: =N19/$N$7 | P19: =F19-N19 | Q19: =N19/F19
... A23: 22 | B23: 16 | C23: =[1]ΑΝΤΙΣΤΟΙΧΙΣΗ!F202 | D23: ='[1]2026_ΕΣΟΔΑ'!D17 | E23: =D23/$D$7 | F23: ='[1]2026 Ιανουάριος'!F23+'2026 Φεβρουάριος'!D23 | G23: =F23/$F$7 | I23: =H23/$H$7 | J23: =H23+'[1]2026 Ιανουάριος'!J23 | K23: =J23/$J$7 | L23: ='[1]2024_60-69 ΕΞΟΔΑ+ΟΜ 2'!D129 | M23: =L23/$L$7 | N23: =L23+'[1]2026 Ιανουάριος'!N23 | O23: =N23/$N$7 | P23: =F23-N23 | Q23: =N23/F23
A24: 23 | B24: 17 | C24: =[1]ΑΝΤΙΣΤΟΙΧΙΣΗ!F203 | D24: ='[1]2026_ΕΣΟΔΑ'!D18 | E24: =D24/$D$7 | F24: ='[1]2026 Ιανουάριος'!F24+'2026 Φεβρουάριος'!D24 | G24: =F24/$F$7 | H24: =[1]ΠΡΟΥΠΟΛΟΓΙΣΜΟΣ_ΕΣΟΔΑ!E225 | I24: =H24/$H$7 | J24: =H24+'[1]2026 Ιανουάριος'!J24 | K24: =J24/$J$7 | L24: ='[1]2024_60-69 ΕΞΟΔΑ+ΟΜ 2'!D130 | M24: =L24/$L$7 | N24: =L24+'[1]2026 Ιανουάριος'!N24 | O24: =N24/$N$7 | P24: =F24-N24 | Q24: =N24/F24
A25: 24 | B25: 18 | C25: =[1]ΑΝΤΙΣΤΟΙΧΙΣΗ!F204 | D25: ='[1]2026_ΕΣΟΔΑ'!D19 | E25: =D25/$D$7 | F25: ='[1]2026 Ιανουάριος'!F25+'2026 Φεβρουάριος'!D25 | G25: =F25/$F$7 | I25: =H25/$H$7 | J25: =H25+'[1]2026 Ιανουάριος'!J25 | K25: =J25/$J$7 | L25: ='[1]2024_60-69 ΕΞΟΔΑ+ΟΜ 2'!D131 | M25: =L25/$L$7 | N25: =L25+'[1]2026 Ιανουάριος'!N25 | O25: =N25/$N$7 | P25: =F25-N25 | Q25: =N25/F25
A26: 25 | B26: 19 | C26: =[1]ΑΝΤΙΣΤΟΙΧΙΣΗ!F205 | D26: ='[1]2026_ΕΣΟΔΑ'!D20 | E26: =D26/$D$7 | F26: ='[1]2026 Ιανουάριος'!F26+'2026 Φεβρουάριος'!D26 | G26: =F26/$F$7 | I26: =H26/$H$7 | J26: =H26+'[1]2026 Ιανουάριος'!J26 | K26: =J26/$J$7 | L26: ='[1]2024_60-69 ΕΞΟΔΑ+ΟΜ 2'!D132 | M26: =L26/$L$7 | N26: =L26+'[1]2026 Ιανουάριος'!N26 | O26: =N26/$N$7 | P26: =F26-N26 | Q26: =N26/F26
A27: 26 | B27: 20 | C27: =[1]ΑΝΤΙΣΤΟΙΧΙΣΗ!F206 | D27: ='[1]2026_ΕΣΟΔΑ'!D21 | E27: =D27/$D$7 | F27: ='[1]2026 Ιανουάριος'!F27+'2026 Φεβρουάριος'!D27 | G27: =F27/$F$7 | I27: =H27/$H$7 | J27: =H27+'[1]2026 Ιανουάριος'!J27 | K27: =J27/$J$7 | L27: ='[1]2024_60-69 ΕΞΟΔΑ+ΟΜ 2'!D133 | M27: =L27/$L$7 | N27: =L27+'[1]2026 Ιανουάριος'!N27 | O27: =N27/$N$7 | P27: =F27-N27 | Q27: =N27/F27
A28: 27 | B28: 21 | C28: =[1]ΑΝΤΙΣΤΟΙΧΙΣΗ!F207 | D28: ='[1]2026_ΕΣΟΔΑ'!D22 | E28: =D28/$D$7 | F28: ='[1]2026 Ιανουάριος'!F28+'2026 Φεβρουάριος'!D28 | G28: =F28/$F$7 | I28: =H28/$H$7 | J28: =H28+'[1]2026 Ιανουάριος'!J28 | K28: =J28/$J$7 | L28: ='[1]2024_60-69 ΕΞΟΔΑ+ΟΜ 2'!D134 | M28: =L28/$L$7 | N28: =L28+'[1]2026 Ιανουάριος'!N28 | O28: =N28/$N$7 | P28: =F28-N28 | Q28: =N28/F28
A29: 28 | B29: 22 | C29: =[1]ΑΝΤΙΣΤΟΙΧΙΣΗ!F208 | D29: ='[1]2026_ΕΣΟΔΑ'!D23 | E29: =D29/$D$7 | F29: ='[1]2026 Ιανουάριος'!F29+'2026 Φεβρουάριος'!D29 | G29: =F29/$F$7 | I29: =H29/$H$7 | J29: =H29+'[1]2026 Ιανουάριος'!J29 | K29: =J29/$J$7 | L29: ='[1]2024_60-69 ΕΞΟΔΑ+ΟΜ 2'!D135 | M29: =L29/$L$7 | N29: =L29+'[1]2026 Ιανουάριος'!N29 | O29: =N29/$N$7 | P29: =F29-N29 | Q29: =N29/F29
A30: 29 | B30: 23 | C30: =[1]ΑΝΤΙΣΤΟΙΧΙΣΗ!F209 | D30: ='[1]2026_ΕΣΟΔΑ'!D24 | E30: =D30/$D$7 | F30: ='[1]2026 Ιανουάριος'!F30+'2026 Φεβρουάριος'!D30 | G30: =F30/$F$7 | I30: =H30/$H$7 | J30: =H30+'[1]2026 Ιανουάριος'!J30 | K30: =J30/$J$7 | L30: ='[1]2024_60-69 ΕΞΟΔΑ+ΟΜ 2'!D136 | M30: =L30/$L$7 | N30: =L30+'[1]2026 Ιανουάριος'!N30 | O30: =N30/$N$7 | P30: =F30-N30 | Q30: =N30/F30
A31: 30 | B31: 24 | C31: =[1]ΑΝΤΙΣΤΟΙΧΙΣΗ!F210 | D31: ='[1]2026_ΕΣΟΔΑ'!D25 | E31: =D31/$D$7 | F31: ='[1]2026 Ιανουάριος'!F31+'2026 Φεβρουάριος'!D31 | G31: =F31/$F$7 | I31: =H31/$H$7 | J31: =H31+'[1]2026 Ιανουάριος'!J31 | K31: =J31/$J$7 | L31: ='[1]2024_60-69 ΕΞΟΔΑ+ΟΜ 2'!D137 | M31: =L31/$L$7 | N31: =L31+'[1]2026 Ιανουάριος'!N31 | O31: =N31/$N$7 | P31: =F31-N31 | Q31: =N31/F31
A32: 31 | B32: 25 | C32: =[1]ΑΝΤΙΣΤΟΙΧΙΣΗ!F211 | D32: ='[1]2026_ΕΣΟΔΑ'!D26 | E32: =D32/$D$7 | F32: ='[1]2026 Ιανουάριος'!F32+'2026 Φεβρουάριος'!D32 | G32: =F32/$F$7 | I32: =H32/$H$7 | J32: =H32+'[1]2026 Ιανουάριος'!J32 | K32: =J32/$J$7 | L32: ='[1]2024_60-69 ΕΞΟΔΑ+ΟΜ 2'!D138 | M32: =L32/$L$7 | N32: =L32+'[1]2026 Ιανουάριος'!N32 | O32: =N32/$N$7 | P32: =F32-N32 | Q32: =N32/F32
A33: 32 | B33: 26 | C33: =[1]ΑΝΤΙΣΤΟΙΧΙΣΗ!F212 | D33: ='[1]2026_ΕΣΟΔΑ'!D27 | E33: =D33/$D$7 | F33: ='[1]2026 Ιανουάριος'!F33+'2026 Φεβρουάριος'!D33 | G33: =F33/$F$7 | I33: =H33/$H$7 | J33: =H33+'[1]2026 Ιανουάριος'!J33 | K33: =J33/$J$7 | L33: ='[1]2024_60-69 ΕΞΟΔΑ+ΟΜ 2'!D139 | M33: =L33/$L$7 | N33: =L33+'[1]2026 Ιανουάριος'!N33 | O33: =N33/$N$7 | P33: =F33-N33 | Q33: =N33/F33
A34: 33 | B34: 27 | C34: =[1]ΑΝΤΙΣΤΟΙΧΙΣΗ!F213 | D34: ='[1]2026_ΕΣΟΔΑ'!D28 | E34: =D34/$D$7 | F34: ='[1]2026 Ιανουάριος'!F34+'2026 Φεβρουάριος'!D34 | G34: =F34/$F$7 | I34: =H34/$H$7 | J34: =H34+'[1]2026 Ιανουάριος'!J34 | K34: =J34/$J$7 | L34: ='[1]2024_60-69 ΕΞΟΔΑ+ΟΜ 2'!D140 | M34: =L34/$L$7 | N34: =L34+'[1]2026 Ιανουάριος'!N34 | O34: =N34/$N$7 | P34: =F34-N34 | Q34: =N34/F34
A35: 34 | B35: 28 | C35: =[1]ΑΝΤΙΣΤΟΙΧΙΣΗ!F214 | D35: ='[1]2026_ΕΣΟΔΑ'!D29 | E35: =D35/$D$7 | F35: ='[1]2026 Ιανουάριος'!F35+'2026 Φεβρουάριος'!D35 | G35: =F35/$F$7 | I35: =H35/$H$7 | J35: =H35+'[1]2026 Ιανουάριος'!J35 | K35: =J35/$J$7 | L35: ='[1]2024_60-69 ΕΞΟΔΑ+ΟΜ 2'!D141 | M35: =L35/$L$7 | N35: =L35+'[1]2026 Ιανουάριος'!N35 | O35: =N35/$N$7 | P35: =F35-N35 | Q35: =N35/F35
A36: 35 | B36: 29 | C36: =[1]ΑΝΤΙΣΤΟΙΧΙΣΗ!F215 | D36: ='[1]2026_ΕΣΟΔΑ'!D30 | E36: =D36/$D$7 | F36: ='[1]2026 Ιανουάριος'!F36+'2026 Φεβρουάριος'!D36 | G36: =F36/$F$7 | I36: =H36/$H$7 | J36: =H36+'[1]2026 Ιανουάριος'!J36 | K36: =J36/$J$7 | L36: ='[1]2024_60-69 ΕΞΟΔΑ+ΟΜ 2'!D142 | M36: =L36/$L$7 | N36: =L36+'[1]2026 Ιανουάριος'!N36 | O36: =N36/$N$7 | P36: =F36-N36 | Q36: =N36/F36
A37: 36 | B37: 30 | C37: =[1]ΑΝΤΙΣΤΟΙΧΙΣΗ!F216 | D37: ='[1]2026_ΕΣΟΔΑ'!D31 | E37: =D37/$D$7 | F37: ='[1]2026 Ιανουάριος'!F37+'2026 Φεβρουάριος'!D37 | G37: =F37/$F$7 | I37: =H37/$H$7 | J37: =H37+'[1]2026 Ιανουάριος'!J37 | K37: =J37/$J$7 | L37: ='[1]2024_60-69 ΕΞΟΔΑ+ΟΜ 2'!D143 | M37: =L37/$L$7 | N37: =L37+'[1]2026 Ιανουάριος'!N37 | O37: =N37/$N$7 | P37: =F37-N37 | Q37: =N37/F37
A38: 37 | C38: ΣΥΝΟΛΟ ΕΣΟΔΩΝ ΜΗΝΟΣ | D38: ='[1]2026_ΕΣΟΔΑ'!D32 | F38: ='[1]2026_ΕΣΟΔΑ'!D34 | H38: =SUM(H8:H31) | J38: =SUM(J8:J31) | L38: =SUM(L8:L31) | N38: =SUM(N8:N31) | P38: =SUM(P8:P31)
A39: 38 | C39: Ελεγχος Ορθότητας ( πρέπει να είναι 0) | D39: =D7-D38 | F39: =F7-F38 | H39: =H7-H38 | J39: =J7-J38 | L39: =L7-L38 | N39: =N7-N38 | P39: =P7-P38
A40: 39 | C40: ΑΝΑΛΥΣΗ ΕΤΟΥΣ 2026 | D40: =[1]ΑΝΤΙΣΤΟΙΧΙΣΗ!$F$32 | H40: =[1]ΑΝΤΙΣΤΟΙΧΙΣΗ!$F$35 | L40: =[1]ΑΝΤΙΣΤΟΙΧΙΣΗ!$F$68 | P40: =[1]ΑΝΤΙΣΤΟΙΧΙΣΗ!$F$100
A41: 40 | C41: ΠΕΡΙΟΔΟΣ | D41: =[1]ΑΝΤΙΣΤΟΙΧΙΣΗ!$F$107 | G41: =[1]ΑΝΤΙΣΤΟΙΧΙΣΗ!$D$34 | H41: =[1]ΑΝΤΙΣΤΟΙΧΙΣΗ!$F$107 | K41: =[1]ΑΝΤΙΣΤΟΙΧΙΣΗ!$D$34 | L41: =[1]ΑΝΤΙΣΤΟΙΧΙΣΗ!$F$121 | O41: =[1]ΑΝΤΙΣΤΟΙΧΙΣΗ!$D$33
A42: 41 | B42: Β | C42: ΚΑΤΗΓΟΡΙΑ ΕΞΟΔΟΥ | D42: Ποσά | E42: % Εξοδο Γραμμής /Σύν.Εξόδων μηνός | F42: Προοδ Σύν. Κατηγ. Εξόδων έως Σήμερα | G42: % Προοδ. Σύνολο Κατηγ. Εξ./ Προοδ. Σύνολο Εξόδων Έως σήμερα | H42: Αμ. Κόστ. Υπηρ. Μηνός | I42: % Εξοδο Γραμμής /Σύν.Εξόδων μηνός | J42: Προοδ Σύν. Κατηγ. Εξόδων έως Σήμερα | K42: % Προοδ. Σύνολο Κατηγ. Εξ./ Προοδ. Σύνολο Εξόδων Έως σήμερα | L42: Αμ. Κόστ. Υπηρ. Μηνός | M42: % Κατηγ.Εξ/Σύν.Αμ.Κο.Υπ.μηνός | N42: Προοδ Σύν. Κατηγ. Εξ έως Σήμερα | O42: % Προοδ. Σύν. Κατηγ. Εξ/ Προοδ. Σύνολο Εξόδων | P42: Προοδ. Διαφορά με Προηγ. Έτος ( Τρέχον Έτος - Προηγ. Έτος) | Q42: % Προοδ.Σύν Κατηγ. Εξ. Πρ. Έτους / Προοδ.Σύν.Εξ. Τρέχοντος Έτους
A43: 42 | B43: Α/Α | C43: Αμεσο Κόστος Υπηρεσιών | D43: =SUM(D44:D77) | F43: =SUM(F44:F77) | H43: =SUM(H44:H77) | J43: =SUM(J44:J77) | L43: =SUM(L44:L77) | N43: =SUM(N44:N77) | P43: =SUM(P44:P77)
...

Sheet 2026 Μάρτιος
A1: ΑΝΑΛΥΣΗ ΑΠΟΤΕΛΕΣΜΑΤΟΣ ΜΗΝΟΣ
A2: 1 | C2: ΑΝΑΛΥΣΗ ΕΤΟΥΣ 2026 | D2: =[1]ΑΝΤΙΣΤΟΙΧΙΣΗ!$F$32 | H2: =[1]ΑΝΤΙΣΤΟΙΧΙΣΗ!$F$35 | L2: =[1]ΑΝΤΙΣΤΟΙΧΙΣΗ!$F$68 | P2: =[1]ΑΝΤΙΣΤΟΙΧΙΣΗ!$F$100
A3: 2 | C3: ΕΙΔΟΣ ΕΣΟΔΩΝ | D3: =[1]ΑΝΤΙΣΤΟΙΧΙΣΗ!$F$108 | G3: =[1]ΑΝΤΙΣΤΟΙΧΙΣΗ!$D$34 | H3: =[1]ΑΝΤΙΣΤΟΙΧΙΣΗ!$F$108 | K3: =[1]ΑΝΤΙΣΤΟΙΧΙΣΗ!$D$34 | L3: =[1]ΑΝΤΙΣΤΟΙΧΙΣΗ!$F$122 | O3: =[1]ΑΝΤΙΣΤΟΙΧΙΣΗ!$D$33
A4: 3 | B4: Α | C4: Κατηγορία Εσόδου | D4: Εσοδο Μηνός | E4: % Εσοδο Γραμμής/Σύν.Εσ.Μηνός | F4: Προοδευτικό Σύνολο Εσόδων έως σήμερα | G4: % Προοδ.Σύνολο Κατηγ. Εσ. /Προοδ.Σύν.Εσ. Έως σήμερα | H4: Εσοδο Μηνός | I4: % Εσοδο Γραμμής /Σύν.Εσ.Μηνός | J4: Προοδευτικό έως σήμερα | K4: % Προοδ.Σύνολο Κατηγ. Εσ. /Προοδ.Σύν.Εσ. Έως σήμερα | L4: Εσοδο Μηνός 2024 | M4: % Εσοδο Γραμμής/Σύν.Εσ.Μηνός | N4: Προοδευτικό Σύνολο Εσόδων έως Τρέχοντα μήνα | O4: % Προοδ.Σύνολο Κατηγ. Εσ. /Προοδ.Σύν.Εσ. Έως σήμερα | P4: Προοδ. Διαφορά Συν. Πραγμ.Τρ. Έτους - Αντιστ. Προοδ. Σύν. Πραγμ. Προηγ. Έτους | Q4: % Προοδ. Διαφορά Κατηγ. Εσ. / Προοδ.Σύν.Προυπ. Εσ. Τρέχοντος Έτους
A5: 4 | C5: Λογιστικό Αποτέλεσμα μηνός | D5: =D7-D6 | F5: =F7-F6 | H5: =H159-H6 | J5: =J159-J6 | L5: =L7-L6 | N5: =N7-N6 | P5: =P159-P6
A6: 5 | C6: Σύνολο Εξόδων Μηνός | D6: =D43+D84+D116 | F6: =F78+F111+F157 | H6: =H38-H43-H84 | J6: =J38-J43-J84 | L6: =L43+L84+L116 | N6: =N78+N111+N157 | P6: =P38-P43-P84
A7: 6 | B7: Α/Α | C7: Σύνολο Εσόδων Μηνός | D7: =SUM(D8:D37) | F7: =SUM(F8:F37) | H7: =SUM(H8:H31) | J7: =SUM(J8:J31) | L7: =SUM(L8:L31) | N7: =L7+'[1]2026 Φεβρουάριος'!N7 | P7: =SUM(P8:P31)
A8: 7 | B8: 1 | C8: =[1]ΑΝΤΙΣΤΟΙΧΙΣΗ!F187 | D8: ='[1]2026_ΕΣΟΔΑ'!E2 | E8: =D8/$D$7 | F8: =D8+'[1]2026 Φεβρουάριος'!F8 | G8: =F8/$F$7 | I8: =H8/$H$7 | J8: =H8+'[1]2026 Φεβρουάριος'!J8 | K8: =J8/$J$7 | L8: ='[1]2024_60-69 ΕΞΟΔΑ+ΟΜ 2'!E114 | M8: =L8/$L$7 | N8: =L8+'[1]2026 Φεβρουάριος'!N8 | O8: =N8/$N$7 | P8: =F8-N8 | Q8: =N8/F8
A9: 8 | B9: 2 | C9: =[1]ΑΝΤΙΣΤΟΙΧΙΣΗ!F188 | D9: ='[1]2026_ΕΣΟΔΑ'!E3 | E9: =D9/$D$7 | F9: =D9+'[1]2026 Φεβρουάριος'!F9 | G9: =F9/$F$7 | I9: =H9/$H$7 | J9: =H9+'[1]2026 Φεβρουάριος'!J9 | K9: =J9/$J$7 | L9: ='[1]2024_60-69 ΕΞΟΔΑ+ΟΜ 2'!E115 | M9: =L9/$L$7 | N9: =L9+'[1]2026 Φεβρουάριος'!N9 | O9: =N9/$N$7 | P9: =F9-N9 | Q9: =N9/F9
A10: 9 | B10: 3 | C10: =[1]ΑΝΤΙΣΤΟΙΧΙΣΗ!F189 | D10: ='[1]2026_ΕΣΟΔΑ'!E4 | E10: =D10/$D$7 | F10: =D10+'[1]2026 Φεβρουάριος'!F10 | G10: =F10/$F$7 | I10: =H10/$H$7 | J10: =H10+'[1]2026 Φεβρουάριος'!J10 | K10: =J10/$J$7 | L10: ='[1]2024_60-69 ΕΞΟΔΑ+ΟΜ 2'!E116 | M10: =L10/$L$7 | N10: =L10+'[1]2026 Φεβρουάριος'!N10 | O10: =N10/$N$7 | P10: =F10-N10 | Q10: =N10/F10
A11: 10 | B11: 4 | C11: =[1]ΑΝΤΙΣΤΟΙΧΙΣΗ!F190 | D11: ='[1]2026_ΕΣΟΔΑ'!E5 | E11: =D11/$D$7 | F11: =D11+'[1]2026 Φεβρουάριος'!F11 | G11: =F11/$F$7 | I11: =H11/$H$7 | J11: =H11+'[1]2026 Φεβρουάριος'!J11 | K11: =J11/$J$7 | L11: ='[1]2024_60-69 ΕΞΟΔΑ+ΟΜ 2'!E117 | M11: =L11/$L$7 | N11: =L11+'[1]2026 Φεβρουάριος'!N11 | O11: =N11/$N$7 | P11: =F11-N11 | Q11: =N11/F11
A12: 11 | B12: 5 | C12: =[1]ΑΝΤΙΣΤΟΙΧΙΣΗ!F191 | D12: ='[1]2026_ΕΣΟΔΑ'!E6 | E12: =D12/$D$7 | F12: =D12+'[1]2026 Φεβρουάριος'!F12 | G12: =F12/$F$7 | I12: =H12/$H$7 | J12: =H12+'[1]2026 Φεβρουάριος'!J12 | K12: =J12/$J$7 | L12: ='[1]2024_60-69 ΕΞΟΔΑ+ΟΜ 2'!E118 | M12: =L12/$L$7 | N12: =L12+'[1]2026 Φεβρουάριος'!N12 | O12: =N12/$N$7 | P12: =F12-N12 | Q12: =N12/F12
A13: 12 | B13: 6 | C13: =[1]ΑΝΤΙΣΤΟΙΧΙΣΗ!F192 | D13: ='[1]2026_ΕΣΟΔΑ'!E7 | E13: =D13/$D$7 | F13: =D13+'[1]2026 Φεβρουάριος'!F13 | G13: =F13/$F$7 | I13: =H13/$H$7 | J13: =H13+'[1]2026 Φεβρουάριος'!J13 | K13: =J13/$J$7 | L13: ='[1]2024_60-69 ΕΞΟΔΑ+ΟΜ 2'!E119 | M13: =L13/$L$7 | N13: =L13+'[1]2026 Φεβρουάριος'!N13 | O13: =N13/$N$7 | P13: =F13-N13 | Q13: =N13/F13
A14: 13 | B14: 7 | C14: =[1]ΑΝΤΙΣΤΟΙΧΙΣΗ!F193 | D14: ='[1]2026_ΕΣΟΔΑ'!E8 | E14: =D14/$D$7 | F14: =D14+'[1]2026 Φεβρουάριος'!F14 | G14: =F14/$F$7 | I14: =H14/$H$7 | J14: =H14+'[1]2026 Φεβρουάριος'!J14 | K14: =J14/$J$7 | L14: ='[1]2024_60-69 ΕΞΟΔΑ+ΟΜ 2'!E120 | M14: =L14/$L$7 | N14: =L14+'[1]2026 Φεβρουάριος'!N14 | O14: =N14/$N$7 | P14: =F14-N14 | Q14: =N14/F14
A15: 14 | B15: 8 | C15: =[1]ΑΝΤΙΣΤΟΙΧΙΣΗ!F194 | D15: ='[1]2026_ΕΣΟΔΑ'!E9 | E15: =D15/$D$7 | F15: =D15+'[1]2026 Φεβρουάριος'!F15 | G15: =F15/$F$7 | I15: =H15/$H$7 | J15: =H15+'[1]2026 Φεβρουάριος'!J15 | K15: =J15/$J$7 | L15: ='[1]2024_60-69 ΕΞΟΔΑ+ΟΜ 2'!E121 | M15: =L15/$L$7 | N15: =L15+'[1]2026 Φεβρουάριος'!N15 | O15: =N15/$N$7 | P15: =F15-N15 | Q15: =N15/F15
A16: 15 | B16: 9 | C16: =[1]ΑΝΤΙΣΤΟΙΧΙΣΗ!F195 | D16: ='[1]2026_ΕΣΟΔΑ'!E10 | E16: =D16/$D$7 | F16: =D16+'[1]2026 Φεβρουάριος'!F16 | G16: =F16/$F$7 | I16: =H16/$H$7 | J16: =H16+'[1]2026 Φεβρουάριος'!J16 | K16: =J16/$J$7 | L16: ='[1]2024_60-69 ΕΞΟΔΑ+ΟΜ 2'!E122 | M16: =L16/$L$7 | N16: =L16+'[1]2026 Φεβρουάριος'!N16 | O16: =N16/$N$7 | P16: =F16-N16 | Q16: =N16/F16
A17: 16 | B17: 10 | C17: =[1]ΑΝΤΙΣΤΟΙΧΙΣΗ!F196 | D17: ='[1]2026_ΕΣΟΔΑ'!E11 | E17: =D17/$D$7 | F17: =D17+'[1]2026 Φεβρουάριος'!F17 | G17: =F17/$F$7 | I17: =H17/$H$7 | J17: =H17+'[1]2026 Φεβρουάριος'!J17 | K17: =J17/$J$7 | L17: ='[1]2024_60-69 ΕΞΟΔΑ+ΟΜ 2'!E123 | M17: =L17/$L$7 | N17: =L17+'[1]2026 Φεβρουάριος'!N17 | O17: =N17/$N$7 | P17: =F17-N17 | Q17: =N17/F17
A18: 17 | B18: 11 | C18: =[1]ΑΝΤΙΣΤΟΙΧΙΣΗ!F197 | D18: ='[1]2026_ΕΣΟΔΑ'!E12 | E18: =D18/$D$7 | F18: =D18+'[1]2026 Φεβρουάριος'!F18 | G18: =F18/$F$7 | I18: =H18/$H$7 | J18: =H18+'[1]2026 Φεβρουάριος'!J18 | K18: =J18/$J$7 | L18: ='[1]2024_60-69 ΕΞΟΔΑ+ΟΜ 2'!E124 | M18: =L18/$L$7 | N18: =L18+'[1]2026 Φεβρουάριος'!N18 | O18: =N18/$N$7 | P18: =F18-N18 | Q18: =N18/F18
A19: 18 | B19: 12 | C19: =[1]ΑΝΤΙΣΤΟΙΧΙΣΗ!F198 | D19: ='[1]2026_ΕΣΟΔΑ'!E13 | E19: =D19/$D$7 | F19: =D19+'[1]2026 Φεβρουάριος'!F19 | G19: =F19/$F$7 | I19: =H19/$H$7 | J19: =H19+'[1]2026 Φεβρουάριος'!J19 | K19: =J19/$J$7 | L19: ='[1]2024_60-69 ΕΞΟΔΑ+ΟΜ 2'!E125 | M19: =L19/$L$7 | N19: =L19+'[1]2026 Φεβρουάριος'!N19 | O19: =N19/$N$7 | P19: =F19-N19 | Q19: =N19/F19
... A23: 22 | B23: 16 | C23: =[1]ΑΝΤΙΣΤΟΙΧΙΣΗ!F202 | D23: ='[1]2026_ΕΣΟΔΑ'!E17 | E23: =D23/$D$7 | F23: =D23+'[1]2026 Φεβρουάριος'!F23 | G23: =F23/$F$7 | I23: =H23/$H$7 | J23: =H23+'[1]2026 Φεβρουάριος'!J23 | K23: =J23/$J$7 | L23: ='[1]2024_60-69 ΕΞΟΔΑ+ΟΜ 2'!E129 | M23: =L23/$L$7 | N23: =L23+'[1]2026 Φεβρουάριος'!N23 | O23: =N23/$N$7 | P23: =F23-N23 | Q23: =N23/F23
A24: 23 | B24: 17 | C24: =[1]ΑΝΤΙΣΤΟΙΧΙΣΗ!F203 | D24: ='[1]2026_ΕΣΟΔΑ'!E18 | E24: =D24/$D$7 | F24: =D24+'[1]2026 Φεβρουάριος'!F24 | G24: =F24/$F$7 | H24: =[1]ΠΡΟΥΠΟΛΟΓΙΣΜΟΣ_ΕΣΟΔΑ!E225 | I24: =H24/$H$7 | J24: =H24+'[1]2026 Φεβρουάριος'!J24 | K24: =J24/$J$7 | L24: ='[1]2024_60-69 ΕΞΟΔΑ+ΟΜ 2'!E130 | M24: =L24/$L$7 | N24: =L24+'[1]2026 Φεβρουάριος'!N24 | O24: =N24/$N$7 | P24: =F24-N24 | Q24: =N24/F24
A25: 24 | B25: 18 | C25: =[1]ΑΝΤΙΣΤΟΙΧΙΣΗ!F204 | D25: ='[1]2026_ΕΣΟΔΑ'!E19 | E25: =D25/$D$7 | F25: =D25+'[1]2026 Φεβρουάριος'!F25 | G25: =F25/$F$7 | I25: =H25/$H$7 | J25: =H25+'[1]2026 Φεβρουάριος'!J25 | K25: =J25/$J$7 | L25: ='[1]2024_60-69 ΕΞΟΔΑ+ΟΜ 2'!E131 | M25: =L25/$L$7 | N25: =L25+'[1]2026 Φεβρουάριος'!N25 | O25: =N25/$N$7 | P25: =F25-N25 | Q25: =N25/F25
A26: 25 | B26: 19 | C26: =[1]ΑΝΤΙΣΤΟΙΧΙΣΗ!F205 | D26: ='[1]2026_ΕΣΟΔΑ'!E20 | E26: =D26/$D$7 | F26: =D26+'[1]2026 Φεβρουάριος'!F26 | G26: =F26/$F$7 | I26: =H26/$H$7 | J26: =H26+'[1]2026 Φεβρουάριος'!J26 | K26: =J26/$J$7 | L26: ='[1]2024_60-69 ΕΞΟΔΑ+ΟΜ 2'!E132 | M26: =L26/$L$7 | N26: =L26+'[1]2026 Φεβρουάριος'!N26 | O26: =N26/$N$7 | P26: =F26-N26 | Q26: =N26/F26
A27: 26 | B27: 20 | C27: =[1]ΑΝΤΙΣΤΟΙΧΙΣΗ!F206 | D27: ='[1]2026_ΕΣΟΔΑ'!E21 | E27: =D27/$D$7 | F27: =D27+'[1]2026 Φεβρουάριος'!F27 | G27: =F27/$F$7 | I27: =H27/$H$7 | J27: =H27+'[1]2026 Φεβρουάριος'!J27 | K27: =J27/$J$7 | L27: ='[1]2024_60-69 ΕΞΟΔΑ+ΟΜ 2'!E133 | M27: =L27/$L$7 | N27: =L27+'[1]2026 Φεβρουάριος'!N27 | O27: =N27/$N$7 | P27: =F27-N27 | Q27: =N27/F27
A28: 27 | B28: 21 | C28: =[1]ΑΝΤΙΣΤΟΙΧΙΣΗ!F207 | D28: ='[1]2026_ΕΣΟΔΑ'!E22 | E28: =D28/$D$7 | F28: =D28+'[1]2026 Φεβρουάριος'!F28 | G28: =F28/$F$7 | I28: =H28/$H$7 | J28: =H28+'[1]2026 Φεβρουάριος'!J28 | K28: =J28/$J$7 | L28: ='[1]2024_60-69 ΕΞΟΔΑ+ΟΜ 2'!E134 | M28: =L28/$L$7 | N28: =L28+'[1]2026 Φεβρουάριος'!N28 | O28: =N28/$N$7 | P28: =F28-N28 | Q28: =N28/F28
A29: 28 | B29: 22 | C29: =[1]ΑΝΤΙΣΤΟΙΧΙΣΗ!F208 | D29: ='[1]2026_ΕΣΟΔΑ'!E23 | E29: =D29/$D$7 | F29: =D29+'[1]2026 Φεβρουάριος'!F29 | G29: =F29/$F$7 | I29: =H29/$H$7 | J29: =H29+'[1]2026 Φεβρουάριος'!J29 | K29: =J29/$J$7 | L29: ='[1]2024_60-69 ΕΞΟΔΑ+ΟΜ 2'!E135 | M29: =L29/$L$7 | N29: =L29+'[1]2026 Φεβρουάριος'!N29 | O29: =N29/$N$7 | P29: =F29-N29 | Q29: =N29/F29
A30: 29 | B30: 23 | C30: =[1]ΑΝΤΙΣΤΟΙΧΙΣΗ!F209 | D30: ='[1]2026_ΕΣΟΔΑ'!E24 | E30: =D30/$D$7 | F30: =D30+'[1]2026 Φεβρουάριος'!F30 | G30: =F30/$F$7 | I30: =H30/$H$7 | J30: =H30+'[1]2026 Φεβρουάριος'!J30 | K30: =J30/$J$7 | L30: ='[1]2024_60-69 ΕΞΟΔΑ+ΟΜ 2'!E136 | M30: =L30/$L$7 | N30: =L30+'[1]2026 Φεβρουάριος'!N30 | O30: =N30/$N$7 | P30: =F30-N30 | Q30: =N30/F30
A31: 30 | B31: 24 | C31: =[1]ΑΝΤΙΣΤΟΙΧΙΣΗ!F210 | D31: ='[1]2026_ΕΣΟΔΑ'!E25 | E31: =D31/$D$7 | F31: =D31+'[1]2026 Φεβρουάριος'!F31 | G31: =F31/$F$7 | I31: =H31/$H$7 | J31: =H31+'[1]2026 Φεβρουάριος'!J31 | K31: =J31/$J$7 | L31: ='[1]2024_60-69 ΕΞΟΔΑ+ΟΜ 2'!E137 | M31: =L31/$L$7 | N31: =L31+'[1]2026 Φεβρουάριος'!N31 | O31: =N31/$N$7 | P31: =F31-N31 | Q31: =N31/F31
A32: 31 | B32: 25 | C32: =[1]ΑΝΤΙΣΤΟΙΧΙΣΗ!F211 | D32: ='[1]2026_ΕΣΟΔΑ'!E26 | E32: =D32/$D$7 | F32: =D32+'[1]2026 Φεβρουάριος'!F32 | G32: =F32/$F$7 | I32: =H32/$H$7 | J32: =H32+'[1]2026 Φεβρουάριος'!J32 | K32: =J32/$J$7 | L32: ='[1]2024_60-69 ΕΞΟΔΑ+ΟΜ 2'!E138 | M32: =L32/$L$7 | N32: =L32+'[1]2026 Φεβρουάριος'!N32 | O32: =N32/$N$7 | P32: =F32-N32 | Q32: =N32/F32
A33: 32 | B33: 26 | C33: =[1]ΑΝΤΙΣΤΟΙΧΙΣΗ!F212 | D33: ='[1]2026_ΕΣΟΔΑ'!E27 | E33: =D33/$D$7 | F33: =D33+'[1]2026 Φεβρουάριος'!F33 | G33: =F33/$F$7 | I33: =H33/$H$7 | J33: =H33+'[1]2026 Φεβρουάριος'!J33 | K33: =J33/$J$7 | L33: ='[1]2024_60-69 ΕΞΟΔΑ+ΟΜ 2'!E139 | M33: =L33/$L$7 | N33: =L33+'[1]2026 Φεβρουάριος'!N33 | O33: =N33/$N$7 | P33: =F33-N33 | Q33: =N33/F33
A34: 33 | B34: 27 | C34: =[1]ΑΝΤΙΣΤΟΙΧΙΣΗ!F213 | D34: ='[1]2026_ΕΣΟΔΑ'!E28 | E34: =D34/$D$7 | F34: =D34+'[1]2026 Φεβρουάριος'!F34 | G34: =F34/$F$7 | I34: =H34/$H$7 | J34: =H34+'[1]2026 Φεβρουάριος'!J34 | K34: =J34/$J$7 | L34: ='[1]2024_60-69 ΕΞΟΔΑ+ΟΜ 2'!E140 | M34: =L34/$L$7 | N34: =L34+'[1]2026 Φεβρουάριος'!N34 | O34: =N34/$N$7 | P34: =F34-N34 | Q34: =N34/F34
A35: 34 | B35: 28 | C35: =[1]ΑΝΤΙΣΤΟΙΧΙΣΗ!F214 | D35: ='[1]2026_ΕΣΟΔΑ'!E29 | E35: =D35/$D$7 | F35: =D35+'[1]2026 Φεβρουάριος'!F35 | G35: =F35/$F$7 | I35: =H35/$H$7 | J35: =H35+'[1]2026 Φεβρουάριος'!J35 | K35: =J35/$J$7 | L35: ='[1]2024_60-69 ΕΞΟΔΑ+ΟΜ 2'!E141 | M35: =L35/$L$7 | N35: =L35+'[1]2026 Φεβρουάριος'!N35 | O35: =N35/$N$7 | P35: =F35-N35 | Q35: =N35/F35
A36: 35 | B36: 29 | C36: =[1]ΑΝΤΙΣΤΟΙΧΙΣΗ!F215 | D36: ='[1]2026_ΕΣΟΔΑ'!E30 | E36: =D36/$D$7 | F36: =D36+'[1]2026 Φεβρουάριος'!F36 | G36: =F36/$F$7 | I36: =H36/$H$7 | J36: =H36+'[1]2026 Φεβρουάριος'!J36 | K36: =J36/$J$7 | L36: ='[1]2024_60-69 ΕΞΟΔΑ+ΟΜ 2'!E142 | M36: =L36/$L$7 | N36: =L36+'[1]2026 Φεβρουάριος'!N36 | O36: =N36/$N$7 | P36: =F36-N36 | Q36: =N36/F36
A37: 36 | B37: 30 | C37: =[1]ΑΝΤΙΣΤΟΙΧΙΣΗ!F216 | D37: ='[1]2026_ΕΣΟΔΑ'!E31 | E37: =D37/$D$7 | F37: =D37+'[1]2026 Φεβρουάριος'!F37 | G37: =F37/$F$7 | I37: =H37/$H$7 | J37: =H37+'[1]2026 Φεβρουάριος'!J37 | K37: =J37/$J$7 | L37: ='[1]2024_60-69 ΕΞΟΔΑ+ΟΜ 2'!E143 | M37: =L37/$L$7 | N37: =L37+'[1]2026 Φεβρουάριος'!N37 | O37: =N37/$N$7 | P37: =F37-N37 | Q37: =N37/F37
A38: 37 | C38: ΣΥΝΟΛΟ ΕΣΟΔΩΝ ΜΗΝΟΣ | D38: ='[1]2026_ΕΣΟΔΑ'!E32 | F38: ='[1]2026_ΕΣΟΔΑ'!E34 | H38: =SUM(H8:H31) | J38: =SUM(J8:J31) | L38: =SUM(L8:L31) | N38: =SUM(N8:N31) | P38: =SUM(P8:P31)
A39: 38 | C39: Ελεγχος Ορθότητας ( πρέπει να είναι 0) | D39: =D7-D38 | F39: =F7-F38 | H39: =H7-H38 | J39: =J7-J38 | L39: =L7-L38 | N39: =N7-N38 | P39: =P7-P38
A40: 39 | C40: ΑΝΑΛΥΣΗ ΕΤΟΥΣ 2026 | D40: =[1]ΑΝΤΙΣΤΟΙΧΙΣΗ!$F$32 | H40: =[1]ΑΝΤΙΣΤΟΙΧΙΣΗ!$F$35 | L40: =[1]ΑΝΤΙΣΤΟΙΧΙΣΗ!$F$68 | P40: =[1]ΑΝΤΙΣΤΟΙΧΙΣΗ!$F$100
A41: 40 | C41: ΠΕΡΙΟΔΟΣ | D41: =[1]ΑΝΤΙΣΤΟΙΧΙΣΗ!$F$108 | G41: =[1]ΑΝΤΙΣΤΟΙΧΙΣΗ!$D$34 | H41: =[1]ΑΝΤΙΣΤΟΙΧΙΣΗ!$F$108 | K41: =[1]ΑΝΤΙΣΤΟΙΧΙΣΗ!$D$34 | L41: =[1]ΑΝΤΙΣΤΟΙΧΙΣΗ!$F$122 | O41: =[1]ΑΝΤΙΣΤΟΙΧΙΣΗ!$D$33
A42: 41 | B42: Β | C42: ΚΑΤΗΓΟΡΙΑ ΕΞΟΔΟΥ | D42: Αμ. Κόστ. Υπηρ. Μηνός | E42: % Εξοδο Γραμμής /Σύν.Εξόδων μηνός | F42: Προοδ Σύν. Κατηγ. Εξόδων έως Σήμερα | G42: % Προοδ. Σύνολο Κατηγ. Εξ./ Προοδ. Σύνολο Εξόδων Έως σήμερα | H42: Αμ. Κόστ. Υπηρ. Μηνός | I42: % Εξοδο Γραμμής /Σύν.Εξόδων μηνός | J42: Προοδ Σύν. Κατηγ. Εξόδων έως Σήμερα | K42: % Προοδ. Σύνολο Κατηγ. Εξ./ Προοδ. Σύνολο Εξόδων Έως σήμερα | L42: Αμ. Κόστ. Υπηρ. Μηνός | M42: % Κατηγ.Εξ/Σύν.Αμ.Κο.Υπ.μηνός | N42: Προοδ Σύν. Κατηγ. Εξ έως Σήμερα | O42: % Προοδ. Σύν. Κατηγ. Εξ/ Προοδ. Σύνολο Εξόδων | P42: Προοδ. Διαφορά με Προηγ. Έτος ( Τρέχον Έτος - Προηγ. Έτος) | Q42: % Προοδ.Σύν Κατηγ. Εξ. Πρ. Έτους / Προοδ.Σύν.Εξ. Τρέχοντος Έτους
A43: 42 | B43: Α/Α | C43: Αμεσο Κόστος Υπηρεσιών | D43: =SUM(D44:D77) | F43: =SUM(F44:F77) | H43: =SUM(H44:H77) | J43: =SUM(J44:J77) | L43: =SUM(L44:L77) | N43: =SUM(N44:N77) | P43: =SUM(P44:P77)
...

Sheet 2026 Απρίλιος
A1: ΑΝΑΛΥΣΗ ΑΠΟΤΕΛΕΣΜΑΤΟΣ ΜΗΝΟΣ
A2: 1 | C2: ΑΝΑΛΥΣΗ ΕΤΟΥΣ 2026 | D2: =[1]ΑΝΤΙΣΤΟΙΧΙΣΗ!$F$32 | H2: =[1]ΑΝΤΙΣΤΟΙΧΙΣΗ!$F$35 | L2: =[1]ΑΝΤΙΣΤΟΙΧΙΣΗ!$F$68 | P2: =[1]ΑΝΤΙΣΤΟΙΧΙΣΗ!$F$100
A3: 2 | C3: ΕΙΔΟΣ ΕΣΟΔΩΝ | D3: =[1]ΑΝΤΙΣΤΟΙΧΙΣΗ!$F$109 | G3: =[1]ΑΝΤΙΣΤΟΙΧΙΣΗ!$D$34 | H3: =[1]ΑΝΤΙΣΤΟΙΧΙΣΗ!$F$109 | K3: =[1]ΑΝΤΙΣΤΟΙΧΙΣΗ!$D$34 | L3: =[1]ΑΝΤΙΣΤΟΙΧΙΣΗ!$F$123 | O3: =[1]ΑΝΤΙΣΤΟΙΧΙΣΗ!$D$33
A4: 3 | B4: Α | C4: Κατηγορία Εσόδου | D4: Εσοδο Μηνός | E4: % Εσοδο Γραμμής/Σύν.Εσ.Μηνός | F4: Προοδευτικό Σύνολο Εσόδων έως σήμερα | G4: % Προοδ.Σύνολο Κατηγ. Εσ. /Προοδ.Σύν.Εσ. Έως σήμερα | H4: Εσοδο Μηνός | I4: % Εσοδο Γραμμής /Σύν.Εσ.Μηνός | J4: Προοδευτικό έως σήμερα | K4: % Προοδ.Σύνολο Κατηγ. Εσ. /Προοδ.Σύν.Εσ. Έως σήμερα | L4: Εσοδο Μηνός 2024 | M4: % Εσοδο Γραμμής/Σύν.Εσ.Μηνός | N4: Προοδευτικό Σύνολο Εσόδων έως Τρέχοντα μήνα | O4: % Προοδ.Σύνολο Κατηγ. Εσ. /Προοδ.Σύν.Εσ. Έως σήμερα | P4: Προοδ. Διαφορά Συν. Πραγμ.Τρ. Έτους - Αντιστ. Προοδ. Σύν. Πραγμ. Προηγ. Έτους | Q4: % Προοδ. Διαφορά Κατηγ. Εσ. / Προοδ.Σύν.Προυπ. Εσ. Τρέχοντος Έτους
A5: 4 | C5: Λογιστικό Αποτέλεσμα μηνός | D5: =D7-D6 | F5: =F7-F6 | H5: =H159-H6 | J5: =J159-J6 | L5: =L7-L6 | N5: =N7-N6 | P5: =P159-P6
A6: 5 | C6: Σύνολο Εξόδων Μηνός | D6: =D43+D84+D116 | F6: =F78+F111+F157 | H6: =H38-H43-H84 | J6: =J38-J43-J84 | L6: =L43+L84+L116 | N6: =N78+N111+N157 | P6: =P38-P43-P84
A7: 6 | B7: Α/Α | C7: Σύνολο Εσόδων Μηνός | D7: =SUM(D8:D37) | F7: =SUM(F8:F37) | H7: =SUM(H8:H31) | J7: =SUM(J8:J31) | L7: =SUM(L8:L31) | N7: =L7+'[1]2026 Μάρτιος'!N7 | P7: =SUM(P8:P31)
A8: 7 | B8: 1 | C8: =[1]ΑΝΤΙΣΤΟΙΧΙΣΗ!F187 | D8: ='[1]2026_ΕΣΟΔΑ'!F2 | E8: =D8/$D$7 | F8: =D8+'[1]2026 Μάρτιος'!F8 | G8: =F8/$F$7 | I8: =H8/$H$7 | J8: =H8+'[1]2026 Μάρτιος'!J8 | K8: =J8/$J$7 | L8: ='[1]2024_60-69 ΕΞΟΔΑ+ΟΜ 2'!F114 | M8: =L8/$L$7 | N8: =L8+'[1]2026 Μάρτιος'!N8 | O8: =N8/$N$7 | P8: =F8-N8 | Q8: =N8/F8
A9: 8 | B9: 2 | C9: =[1]ΑΝΤΙΣΤΟΙΧΙΣΗ!F188 | D9: ='[1]2026_ΕΣΟΔΑ'!F3 | E9: =D9/$D$7 | F9: =D9+'[1]2026 Μάρτιος'!F9 | G9: =F9/$F$7 | I9: =H9/$H$7 | J9: =H9+'[1]2026 Μάρτιος'!J9 | K9: =J9/$J$7 | L9: ='[1]2024_60-69 ΕΞΟΔΑ+ΟΜ 2'!F115 | M9: =L9/$L$7 | N9: =L9+'[1]2026 Μάρτιος'!N9 | O9: =N9/$N$7 | P9: =F9-N9 | Q9: =N9/F9
A10: 9 | B10: 3 | C10: =[1]ΑΝΤΙΣΤΟΙΧΙΣΗ!F189 | D10: ='[1]2026_ΕΣΟΔΑ'!F4 | E10: =D10/$D$7 | F10: =D10+'[1]2026 Μάρτιος'!F10 | G10: =F10/$F$7 | I10: =H10/$H$7 | J10: =H10+'[1]2026 Μάρτιος'!J10 | K10: =J10/$J$7 | L10: ='[1]2024_60-69 ΕΞΟΔΑ+ΟΜ 2'!F116 | M10: =L10/$L$7 | N10: =L10+'[1]2026 Μάρτιος'!N10 | O10: =N10/$N$7 | P10: =F10-N10 | Q10: =N10/F10
A11: 10 | B11: 4 | C11: =[1]ΑΝΤΙΣΤΟΙΧΙΣΗ!F190 | D11: ='[1]2026_ΕΣΟΔΑ'!F5 | E11: =D11/$D$7 | F11: =D11+'[1]2026 Μάρτιος'!F11 | G11: =F11/$F$7 | I11: =H11/$H$7 | J11: =H11+'[1]2026 Μάρτιος'!J11 | K11: =J11/$J$7 | L11: ='[1]2024_60-69 ΕΞΟΔΑ+ΟΜ 2'!F117 | M11: =L11/$L$7 | N11: =L11+'[1]2026 Μάρτιος'!N11 | O11: =N11/$N$7 | P11: =F11-N11 | Q11: =N11/F11
A12: 11 | B12: 5 | C12: =[1]ΑΝΤΙΣΤΟΙΧΙΣΗ!F191 | D12: ='[1]2026_ΕΣΟΔΑ'!F6 | E12: =D12/$D$7 | F12: =D12+'[1]2026 Μάρτιος'!F12 | G12: =F12/$F$7 | I12: =H12/$H$7 | J12: =H12+'[1]2026 Μάρτιος'!J12 | K12: =J12/$J$7 | L12: ='[1]2024_60-69 ΕΞΟΔΑ+ΟΜ 2'!F118 | M12: =L12/$L$7 | N12: =L12+'[1]2026 Μάρτιος'!N12 | O12: =N12/$N$7 | P12: =F12-N12 | Q12: =N12/F12
A13: 12 | B13: 6 | C13: =[1]ΑΝΤΙΣΤΟΙΧΙΣΗ!F192 | D13: ='[1]2026_ΕΣΟΔΑ'!F7 | E13: =D13/$D$7 | F13: =D13+'[1]2026 Μάρτιος'!F13 | G13: =F13/$F$7 | I13: =H13/$H$7 | J13: =H13+'[1]2026 Μάρτιος'!J13 | K13: =J13/$J$7 | L13: ='[1]2024_60-69 ΕΞΟΔΑ+ΟΜ 2'!F119 | M13: =L13/$L$7 | N13: =L13+'[1]2026 Μάρτιος'!N13 | O13: =N13/$N$7 | P13: =F13-N13 | Q13: =N13/F13
A14: 13 | B14: 7 | C14: =[1]ΑΝΤΙΣΤΟΙΧΙΣΗ!F193 | D14: ='[1]2026_ΕΣΟΔΑ'!F8 | E14: =D14/$D$7 | F14: =D14+'[1]2026 Μάρτιος'!F14 | G14: =F14/$F$7 | I14: =H14/$H$7 | J14: =H14+'[1]2026 Μάρτιος'!J14 | K14: =J14/$J$7 | L14: ='[1]2024_60-69 ΕΞΟΔΑ+ΟΜ 2'!F120 | M14: =L14/$L$7 | N14: =L14+'[1]2026 Μάρτιος'!N14 | O14: =N14/$N$7 | P14: =F14-N14 | Q14: =N14/F14
A15: 14 | B15: 8 | C15: =[1]ΑΝΤΙΣΤΟΙΧΙΣΗ!F194 | D15: ='[1]2026_ΕΣΟΔΑ'!F9 | E15: =D15/$D$7 | F15: =D15+'[1]2026 Μάρτιος'!F15 | G15: =F15/$F$7 | I15: =H15/$H$7 | J15: =H15+'[1]2026 Μάρτιος'!J15 | K15: =J15/$J$7 | L15: ='[1]2024_60-69 ΕΞΟΔΑ+ΟΜ 2'!F121 | M15: =L15/$L$7 | N15: =L15+'[1]2026 Μάρτιος'!N15 | O15: =N15/$N$7 | P15: =F15-N15 | Q15: =N15/F15
A16: 15 | B16: 9 | C16: =[1]ΑΝΤΙΣΤΟΙΧΙΣΗ!F195 | D16: ='[1]2026_ΕΣΟΔΑ'!F10 | E16: =D16/$D$7 | F16: =D16+'[1]2026 Μάρτιος'!F16 | G16: =F16/$F$7 | I16: =H16/$H$7 | J16: =H16+'[1]2026 Μάρτιος'!J16 | K16: =J16/$J$7 | L16: ='[1]2024_60-69 ΕΞΟΔΑ+ΟΜ 2'!F122 | M16: =L16/$L$7 | N16: =L16+'[1]2026 Μάρτιος'!N16 | O16: =N16/$N$7 | P16: =F16-N16 | Q16: =N16/F16
A17: 16 | B17: 10 | C17: =[1]ΑΝΤΙΣΤΟΙΧΙΣΗ!F196 | D17: ='[1]2026_ΕΣΟΔΑ'!F11 | E17: =D17/$D$7 | F17: =D17+'[1]2026 Μάρτιος'!F17 | G17: =F17/$F$7 | I17: =H17/$H$7 | J17: =H17+'[1]2026 Μάρτιος'!J17 | K17: =J17/$J$7 | L17: ='[1]2024_60-69 ΕΞΟΔΑ+ΟΜ 2'!F123 | M17: =L17/$L$7 | N17: =L17+'[1]2026 Μάρτιος'!N17 | O17: =N17/$N$7 | P17: =F17-N17 | Q17: =N17/F17
A18: 17 | B18: 11 | C18: =[1]ΑΝΤΙΣΤΟΙΧΙΣΗ!F197 | D18: ='[1]2026_ΕΣΟΔΑ'!F12 | E18: =D18/$D$7 | F18: =D18+'[1]2026 Μάρτιος'!F18 | G18: =F18/$F$7 | I18: =H18/$H$7 | J18: =H18+'[1]2026 Μάρτιος'!J18 | K18: =J18/$J$7 | L18: ='[1]2024_60-69 ΕΞΟΔΑ+ΟΜ 2'!F124 | M18: =L18/$L$7 | N18: =L18+'[1]2026 Μάρτιος'!N18 | O18: =N18/$N$7 | P18: =F18-N18 | Q18: =N18/F18
A19: 18 | B19: 12 | C19: =[1]ΑΝΤΙΣΤΟΙΧΙΣΗ!F198 | D19: ='[1]2026_ΕΣΟΔΑ'!F13 | E19: =D19/$D$7 | F19: =D19+'[1]2026 Μάρτιος'!F19 | G19: =F19/$F$7 | I19: =H19/$H$7 | J19: =H19+'[1]2026 Μάρτιος'!J19 | K19: =J19/$J$7 | L19: ='[1]2024_60-69 ΕΞΟΔΑ+ΟΜ 2'!F125 | M19: =L19/$L$7 | N19: =L19+'[1]2026 Μάρτιος'!N19 | O19: =N19/$N$7 | P19: =F19-N19 | Q19: =N19/F19
... A23: 22 | B23: 16 | C23: =[1]ΑΝΤΙΣΤΟΙΧΙΣΗ!F202 | D23: ='[1]2026_ΕΣΟΔΑ'!F17 | E23: =D23/$D$7 | F23: =D23+'[1]2026 Μάρτιος'!F23 | G23: =F23/$F$7 | I23: =H23/$H$7 | J23: =H23+'[1]2026 Μάρτιος'!J23 | K23: =J23/$J$7 | L23: ='[1]2024_60-69 ΕΞΟΔΑ+ΟΜ 2'!F129 | M23: =L23/$L$7 | N23: =L23+'[1]2026 Μάρτιος'!N23 | O23: =N23/$N$7 | P23: =F23-N23 | Q23: =N23/F23
A24: 23 | B24: 17 | C24: =[1]ΑΝΤΙΣΤΟΙΧΙΣΗ!F203 | D24: ='[1]2026_ΕΣΟΔΑ'!F18 | E24: =D24/$D$7 | F24: =D24+'[1]2026 Μάρτιος'!F24 | G24: =F24/$F$7 | H24: =[1]ΠΡΟΥΠΟΛΟΓΙΣΜΟΣ_ΕΣΟΔΑ!E225 | I24: =H24/$H$7 | J24: =H24+'[1]2026 Μάρτιος'!J24 | K24: =J24/$J$7 | L24: ='[1]2024_60-69 ΕΞΟΔΑ+ΟΜ 2'!F130 | M24: =L24/$L$7 | N24: =L24+'[1]2026 Μάρτιος'!N24 | O24: =N24/$N$7 | P24: =F24-N24 | Q24: =N24/F24
A25: 24 | B25: 18 | C25: =[1]ΑΝΤΙΣΤΟΙΧΙΣΗ!F204 | D25: ='[1]2026_ΕΣΟΔΑ'!F19 | E25: =D25/$D$7 | F25: =D25+'[1]2026 Μάρτιος'!F25 | G25: =F25/$F$7 | I25: =H25/$H$7 | J25: =H25+'[1]2026 Μάρτιος'!J25 | K25: =J25/$J$7 | L25: ='[1]2024_60-69 ΕΞΟΔΑ+ΟΜ 2'!F131 | M25: =L25/$L$7 | N25: =L25+'[1]2026 Μάρτιος'!N25 | O25: =N25/$N$7 | P25: =F25-N25 | Q25: =N25/F25
A26: 25 | B26: 19 | C26: =[1]ΑΝΤΙΣΤΟΙΧΙΣΗ!F205 | D26: ='[1]2026_ΕΣΟΔΑ'!F20 | E26: =D26/$D$7 | F26: =D26+'[1]2026 Μάρτιος'!F26 | G26: =F26/$F$7 | I26: =H26/$H$7 | J26: =H26+'[1]2026 Μάρτιος'!J26 | K26: =J26/$J$7 | L26: ='[1]2024_60-69 ΕΞΟΔΑ+ΟΜ 2'!F132 | M26: =L26/$L$7 | N26: =L26+'[1]2026 Μάρτιος'!N26 | O26: =N26/$N$7 | P26: =F26-N26 | Q26: =N26/F26
A27: 26 | B27: 20 | C27: =[1]ΑΝΤΙΣΤΟΙΧΙΣΗ!F206 | D27: ='[1]2026_ΕΣΟΔΑ'!F21 | E27: =D27/$D$7 | F27: =D27+'[1]2026 Μάρτιος'!F27 | G27: =F27/$F$7 | I27: =H27/$H$7 | J27: =H27+'[1]2026 Μάρτιος'!J27 | K27: =J27/$J$7 | L27: ='[1]2024_60-69 ΕΞΟΔΑ+ΟΜ 2'!F133 | M27: =L27/$L$7 | N27: =L27+'[1]2026 Μάρτιος'!N27 | O27: =N27/$N$7 | P27: =F27-N27 | Q27: =N27/F27
A28: 27 | B28: 21 | C28: =[1]ΑΝΤΙΣΤΟΙΧΙΣΗ!F207 | D28: ='[1]2026_ΕΣΟΔΑ'!F22 | E28: =D28/$D$7 | F28: =D28+'[1]2026 Μάρτιος'!F28 | G28: =F28/$F$7 | I28: =H28/$H$7 | J28: =H28+'[1]2026 Μάρτιος'!J28 | K28: =J28/$J$7 | L28: ='[1]2024_60-69 ΕΞΟΔΑ+ΟΜ 2'!F134 | M28: =L28/$L$7 | N28: =L28+'[1]2026 Μάρτιος'!N28 | O28: =N28/$N$7 | P28: =F28-N28 | Q28: =N28/F28
A29: 28 | B29: 22 | C29: =[1]ΑΝΤΙΣΤΟΙΧΙΣΗ!F208 | D29: ='[1]2026_ΕΣΟΔΑ'!F23 | E29: =D29/$D$7 | F29: =D29+'[1]2026 Μάρτιος'!F29 | G29: =F29/$F$7 | I29: =H29/$H$7 | J29: =H29+'[1]2026 Μάρτιος'!J29 | K29: =J29/$J$7 | L29: ='[1]2024_60-69 ΕΞΟΔΑ+ΟΜ 2'!F135 | M29: =L29/$L$7 | N29: =L29+'[1]2026 Μάρτιος'!N29 | O29: =N29/$N$7 | P29: =F29-N29 | Q29: =N29/F29
A30: 29 | B30: 23 | C30: =[1]ΑΝΤΙΣΤΟΙΧΙΣΗ!F209 | D30: ='[1]2026_ΕΣΟΔΑ'!F24 | E30: =D30/$D$7 | F30: =D30+'[1]2026 Μάρτιος'!F30 | G30: =F30/$F$7 | I30: =H30/$H$7 | J30: =H30+'[1]2026 Μάρτιος'!J30 | K30: =J30/$J$7 | L30: ='[1]2024_60-69 ΕΞΟΔΑ+ΟΜ 2'!F136 | M30: =L30/$L$7 | N30: =L30+'[1]2026 Μάρτιος'!N30 | O30: =N30/$N$7 | P30: =F30-N30 | Q30: =N30/F30
A31: 30 | B31: 24 | C31: =[1]ΑΝΤΙΣΤΟΙΧΙΣΗ!F210 | D31: ='[1]2026_ΕΣΟΔΑ'!F25 | E31: =D31/$D$7 | F31: =D31+'[1]2026 Μάρτιος'!F31 | G31: =F31/$F$7 | I31: =H31/$H$7 | J31: =H31+'[1]2026 Μάρτιος'!J31 | K31: =J31/$J$7 | L31: ='[1]2024_60-69 ΕΞΟΔΑ+ΟΜ 2'!F137 | M31: =L31/$L$7 | N31: =L31+'[1]2026 Μάρτιος'!N31 | O31: =N31/$N$7 | P31: =F31-N31 | Q31: =N31/F31
A32: 31 | B32: 25 | C32: =[1]ΑΝΤΙΣΤΟΙΧΙΣΗ!F211 | D32: ='[1]2026_ΕΣΟΔΑ'!F26 | E32: =D32/$D$7 | F32: =D32+'[1]2026 Μάρτιος'!F32 | G32: =F32/$F$7 | I32: =H32/$H$7 | J32: =H32+'[1]2026 Μάρτιος'!J32 | K32: =J32/$J$7 | L32: ='[1]2024_60-69 ΕΞΟΔΑ+ΟΜ 2'!F138 | M32: =L32/$L$7 | N32: =L32+'[1]2026 Μάρτιος'!N32 | O32: =N32/$N$7 | P32: =F32-N32 | Q32: =N32/F32
A33: 32 | B33: 26 | C33: =[1]ΑΝΤΙΣΤΟΙΧΙΣΗ!F212 | D33: ='[1]2026_ΕΣΟΔΑ'!F27 | E33: =D33/$D$7 | F33: =D33+'[1]2026 Μάρτιος'!F33 | G33: =F33/$F$7 | I33: =H33/$H$7 | J33: =H33+'[1]2026 Μάρτιος'!J33 | K33: =J33/$J$7 | L33: ='[1]2024_60-69 ΕΞΟΔΑ+ΟΜ 2'!F139 | M33: =L33/$L$7 | N33: =L33+'[1]2026 Μάρτιος'!N33 | O33: =N33/$N$7 | P33: =F33-N33 | Q33: =N33/F33
A34: 33 | B34: 27 | C34: =[1]ΑΝΤΙΣΤΟΙΧΙΣΗ!F213 | D34: ='[1]2026_ΕΣΟΔΑ'!F28 | E34: =D34/$D$7 | F34: =D34+'[1]2026 Μάρτιος'!F34 | G34: =F34/$F$7 | I34: =H34/$H$7 | J34: =H34+'[1]2026 Μάρτιος'!J34 | K34: =J34/$J$7 | L34: ='[1]2024_60-69 ΕΞΟΔΑ+ΟΜ 2'!F140 | M34: =L34/$L$7 | N34: =L34+'[1]2026 Μάρτιος'!N34 | O34: =N34/$N$7 | P34: =F34-N34 | Q34: =N34/F34
A35: 34 | B35: 28 | C35: =[1]ΑΝΤΙΣΤΟΙΧΙΣΗ!F214 | D35: ='[1]2026_ΕΣΟΔΑ'!F29 | E35: =D35/$D$7 | F35: =D35+'[1]2026 Μάρτιος'!F35 | G35: =F35/$F$7 | I35: =H35/$H$7 | J35: =H35+'[1]2026 Μάρτιος'!J35 | K35: =J35/$J$7 | L35: ='[1]2024_60-69 ΕΞΟΔΑ+ΟΜ 2'!F141 | M35: =L35/$L$7 | N35: =L35+'[1]2026 Μάρτιος'!N35 | O35: =N35/$N$7 | P35: =F35-N35 | Q35: =N35/F35
A36: 35 | B36: 29 | C36: =[1]ΑΝΤΙΣΤΟΙΧΙΣΗ!F215 | D36: ='[1]2026_ΕΣΟΔΑ'!F30 | E36: =D36/$D$7 | F36: =D36+'[1]2026 Μάρτιος'!F36 | G36: =F36/$F$7 | I36: =H36/$H$7 | J36: =H36+'[1]2026 Μάρτιος'!J36 | K36: =J36/$J$7 | L36: ='[1]2024_60-69 ΕΞΟΔΑ+ΟΜ 2'!F142 | M36: =L36/$L$7 | N36: =L36+'[1]2026 Μάρτιος'!N36 | O36: =N36/$N$7 | P36: =F36-N36 | Q36: =N36/F36
A37: 36 | B37: 30 | C37: =[1]ΑΝΤΙΣΤΟΙΧΙΣΗ!F216 | D37: ='[1]2026_ΕΣΟΔΑ'!F31 | E37: =D37/$D$7 | F37: =D37+'[1]2026 Μάρτιος'!F37 | G37: =F37/$F$7 | I37: =H37/$H$7 | J37: =H37+'[1]2026 Μάρτιος'!J37 | K37: =J37/$J$7 | L37: ='[1]2024_60-69 ΕΞΟΔΑ+ΟΜ 2'!F143 | M37: =L37/$L$7 | N37: =L37+'[1]2026 Μάρτιος'!N37 | O37: =N37/$N$7 | P37: =F37-N37 | Q37: =N37/F37
A38: 37 | C38: ΣΥΝΟΛΟ ΕΣΟΔΩΝ ΜΗΝΟΣ | D38: ='[1]2026_ΕΣΟΔΑ'!F32 | F38: ='[1]2026_ΕΣΟΔΑ'!F34 | H38: =SUM(H8:H31) | J38: =SUM(J8:J31) | L38: =SUM(L8:L31) | N38: =SUM(N8:N31) | P38: =SUM(P8:P31)
A39: 38 | C39: Ελεγχος Ορθότητας ( πρέπει να είναι 0) | D39: =D7-D38 | F39: =F7-F38 | H39: =H7-H38 | J39: =J7-J38 | L39: =L7-L38 | N39: =N7-N38 | P39: =P7-P38
A40: 39 | C40: ΑΝΑΛΥΣΗ ΕΤΟΥΣ 2026 | D40: =[1]ΑΝΤΙΣΤΟΙΧΙΣΗ!$F$32 | H40: =[1]ΑΝΤΙΣΤΟΙΧΙΣΗ!$F$35 | L40: =[1]ΑΝΤΙΣΤΟΙΧΙΣΗ!$F$68 | P40: =[1]ΑΝΤΙΣΤΟΙΧΙΣΗ!$F$100
A41: 40 | C41: ΠΕΡΙΟΔΟΣ | D41: =[1]ΑΝΤΙΣΤΟΙΧΙΣΗ!$F$109 | G41: =[1]ΑΝΤΙΣΤΟΙΧΙΣΗ!$D$34 | H41: =[1]ΑΝΤΙΣΤΟΙΧΙΣΗ!$F$109 | K41: =[1]ΑΝΤΙΣΤΟΙΧΙΣΗ!$D$34 | L41: =[1]ΑΝΤΙΣΤΟΙΧΙΣΗ!$F$123 | O41: =[1]ΑΝΤΙΣΤΟΙΧΙΣΗ!$D$33
A42: 41 | B42: Β | C42: ΚΑΤΗΓΟΡΙΑ ΕΞΟΔΟΥ | E42: % Εξοδο Γραμμής /Σύν.Εξόδων μηνός | F42: Προοδ Σύν. Κατηγ. Εξόδων έως Σήμερα | G42: % Προοδ. Σύνολο Κατηγ. Εξ./ Προοδ. Σύνολο Εξόδων Έως σήμερα | H42: Αμ. Κόστ. Υπηρ. Μηνός | I42: % Εξοδο Γραμμής /Σύν.Εξόδων μηνός | J42: Προοδ Σύν. Κατηγ. Εξόδων έως Σήμερα | K42: % Προοδ. Σύνολο Κατηγ. Εξ./ Προοδ. Σύνολο Εξόδων Έως σήμερα | L42: Αμ. Κόστ. Υπηρ. Μηνός | M42: % Κατηγ.Εξ/Σύν.Αμ.Κο.Υπ.μηνός | N42: Προοδ Σύν. Κατηγ. Εξ έως Σήμερα | O42: % Προοδ. Σύν. Κατηγ. Εξ/ Προοδ. Σύνολο ΕΞόδων | P42: Προοδ. Διαφορά με Προηγ. Έτος ( Τρέχον Έτος - Προηγ. Έτος) | Q42: % Προοδ.Σύν Κατηγ. Εξ. Πρ. Έτους / Προοδ.Σύν.Εξ. Τρέχοντος Έτους
A43: 42 | B43: Α/Α | C43: Αμεσο Κόστος Υπηρεσιών | D43: =SUM(D44:D77) | F43: =SUM(F44:F77) | H43: =SUM(H44:H77) | J43: =SUM(J44:J77) | L43: =SUM(L44:L77) | N43: =SUM(N44:N77) | P43: =SUM(P44:P77)
...

Sheet 2026 Μάιος
A1: ΑΝΑΛΥΣΗ ΑΠΟΤΕΛΕΣΜΑΤΟΣ ΜΗΝΟΣ
A2: 1 | C2: ΑΝΑΛΥΣΗ ΕΤΟΥΣ 2026 | D2: =[1]ΑΝΤΙΣΤΟΙΧΙΣΗ!$F$32 | H2: =[1]ΑΝΤΙΣΤΟΙΧΙΣΗ!$F$35 | L2: =[1]ΑΝΤΙΣΤΟΙΧΙΣΗ!$F$68 | P2: =[1]ΑΝΤΙΣΤΟΙΧΙΣΗ!$F$100
A3: 2 | C3: ΕΙΔΟΣ ΕΣΟΔΩΝ | D3: =[1]ΑΝΤΙΣΤΟΙΧΙΣΗ!$F$110 | G3: =[1]ΑΝΤΙΣΤΟΙΧΙΣΗ!$D$34 | H3: =[1]ΑΝΤΙΣΤΟΙΧΙΣΗ!$F$110 | K3: =[1]ΑΝΤΙΣΤΟΙΧΙΣΗ!$D$34 | L3: =[1]ΑΝΤΙΣΤΟΙΧΙΣΗ!$F$124 | O3: =[1]ΑΝΤΙΣΤΟΙΧΙΣΗ!$D$33
A4: 3 | B4: Α | C4: Κατηγορία Εσόδου | D4: Εσοδο Μηνός | E4: % Εσοδο Γραμμής/Σύν.Εσ.Μηνός | F4: Προοδευτικό Σύνολο Εσόδων έως σήμερα | G4: % Προοδ.Σύνολο Κατηγ. Εσ. /Προοδ.Σύν.Εσ. Έως σήμερα | H4: Εσοδο Μηνός | I4: % Εσοδο Γραμμής /Σύν.Εσ.Μηνός | J4: Προοδευτικό έως σήμερα | K4: % Προοδ.Σύνολο Κατηγ. Εσ. /Προοδ.Σύν.Εσ. Έως σήμερα | L4: Εσοδο Μηνός 2024 | M4: % Εσοδο Γραμμής/Σύν.Εσ.Μηνός | N4: Προοδευτικό Σύνολο Εσόδων έως Τρέχοντα μήνα | O4: % Προοδ.Σύνολο Κατηγ. Εσ. /Προοδ.Σύν.Εσ. Έως σήμερα | P4: Προοδ. Διαφορά Συν. Πραγμ.Τρ. Έτους - Αντιστ. Προοδ. Σύν. Πραγμ. Προηγ. Έτους | Q4: % Προοδ. Διαφορά Κατηγ. Εσ. / Προοδ.Σύν.Προυπ. Εσ. Τρέχοντος Έτους
A5: 4 | C5: Λογιστικό Αποτέλεσμα μηνός | D5: =D7-D6 | F5: =F7-F6 | H5: =H159-H6 | J5: =J159-J6 | L5: =L7-L6 | N5: =N7-N6 | P5: =P159-P6
A6: 5 | C6: Σύνολο Εξόδων Μηνός | D6: =D43+D84+D116 | F6: =F78+F111+F157 | H6: =H38-H43-H84 | J6: =J38-J43-J84 | L6: =L43+L84+L116 | N6: =N78+N111+N157 | P6: =P38-P43-P84
A7: 6 | B7: Α/Α | C7: Σύνολο Εσόδων Μηνός | D7: =SUM(D8:D31) | F7: =SUM(F8:F31) | H7: =SUM(H8:H31) | J7: =SUM(J8:J31) | L7: =SUM(L8:L31) | N7: =L7+'[1]2026 Απρίλιος'!N7 | P7: =SUM(P8:P31)
A8: 7 | B8: 1 | C8: =[1]ΑΝΤΙΣΤΟΙΧΙΣΗ!F187 | D8: ='[1]2026_ΕΣΟΔΑ'!G2 | E8: =D8/$D$7 | F8: =D8+'[1]2026 Απρίλιος'!F8 | G8: =F8/$F$7 | I8: =H8/$H$7 | J8: =H8+'[1]2026 Απρίλιος'!J8 | K8: =J8/$J$7 | L8: ='[1]2024_60-69 ΕΞΟΔΑ+ΟΜ 2'!G114 | M8: =L8/$L$7 | N8: =L8+'[1]2026 Απρίλιος'!N8 | O8: =N8/$N$7 | P8: =F8-N8 | Q8: =N8/F8
A9: 8 | B9: 2 | C9: =[1]ΑΝΤΙΣΤΟΙΧΙΣΗ!F188 | D9: ='[1]2026_ΕΣΟΔΑ'!G3 | E9: =D9/$D$7 | F9: =D9+'[1]2026 Απρίλιος'!F9 | G9: =F9/$F$7 | I9: =H9/$H$7 | J9: =H9+'[1]2026 Απρίλιος'!J9 | K9: =J9/$J$7 | L9: ='[1]2024_60-69 ΕΞΟΔΑ+ΟΜ 2'!G115 | M9: =L9/$L$7 | N9: =L9+'[1]2026 Απρίλιος'!N9 | O9: =N9/$N$7 | P9: =F9-N9 | Q9: =N9/F9
A10: 9 | B10: 3 | C10: =[1]ΑΝΤΙΣΤΟΙΧΙΣΗ!F189 | D10: ='[1]2026_ΕΣΟΔΑ'!G4 | E10: =D10/$D$7 | F10: =D10+'[1]2026 Απρίλιος'!F10 | G10: =F10/$F$7 | I10: =H10/$H$7 | J10: =H10+'[1]2026 Απρίλιος'!J10 | K10: =J10/$J$7 | L10: ='[1]2024_60-69 ΕΞΟΔΑ+ΟΜ 2'!G116 | M10: =L10/$L$7 | N10: =L10+'[1]2026 Απρίλιος'!N10 | O10: =N10/$N$7 | P10: =F10-N10 | Q10: =N10/F10
A11: 10 | B11: 4 | C11: =[1]ΑΝΤΙΣΤΟΙΧΙΣΗ!F190 | D11: ='[1]2026_ΕΣΟΔΑ'!G5 | E11: =D11/$D$7 | F11: =D11+'[1]2026 Απρίλιος'!F11 | G11: =F11/$F$7 | I11: =H11/$H$7 | J11: =H11+'[1]2026 Απρίλιος'!J11 | K11: =J11/$J$7 | L11: ='[1]2024_60-69 ΕΞΟΔΑ+ΟΜ 2'!G117 | M11: =L11/$L$7 | N11: =L11+'[1]2026 Απρίλιος'!N11 | O11: =N11/$N$7 | P11: =F11-N11 | Q11: =N11/F11
A12: 11 | B12: 5 | C12: =[1]ΑΝΤΙΣΤΟΙΧΙΣΗ!F191 | D12: ='[1]2026_ΕΣΟΔΑ'!G6 | E12: =D12/$D$7 | F12: =D12+'[1]2026 Απρίλιος'!F12 | G12: =F12/$F$7 | I12: =H12/$H$7 | J12: =H12+'[1]2026 Απρίλιος'!J12 | K12: =J12/$J$7 | L12: ='[1]2024_60-69 ΕΞΟΔΑ+ΟΜ 2'!G118 | M12: =L12/$L$7 | N12: =L12+'[1]2026 Απρίλιος'!N12 | O12: =N12/$N$7 | P12: =F12-N12 | Q12: =N12/F12
A13: 12 | B13: 6 | C13: =[1]ΑΝΤΙΣΤΟΙΧΙΣΗ!F192 | D13: ='[1]2026_ΕΣΟΔΑ'!G7 | E13: =D13/$D$7 | F13: =D13+'[1]2026 Απρίλιος'!F13 | G13: =F13/$F$7 | I13: =H13/$H$7 | J13: =H13+'[1]2026 Απρίλιος'!J13 | K13: =J13/$J$7 | L13: ='[1]2024_60-69 ΕΞΟΔΑ+ΟΜ 2'!G119 | M13: =L13/$L$7 | N13: =L13+'[1]2026 Απρίλιος'!N13 | O13: =N13/$N$7 | P13: =F13-N13 | Q13: =N13/F13
A14: 13 | B14: 7 | C14: =[1]ΑΝΤΙΣΤΟΙΧΙΣΗ!F193 | D14: ='[1]2026_ΕΣΟΔΑ'!G8 | E14: =D14/$D$7 | F14: =D14+'[1]2026 Απρίλιος'!F14 | G14: =F14/$F$7 | I14: =H14/$H$7 | J14: =H14+'[1]2026 Απρίλιος'!J14 | K14: =J14/$J$7 | L14: ='[1]2024_60-69 ΕΞΟΔΑ+ΟΜ 2'!G120 | M14: =L14/$L$7 | N14: =L14+'[1]2026 Απρίλιος'!N14 | O14: =N14/$N$7 | P14: =F14-N14 | Q14: =N14/F14
A15: 14 | B15: 8 | C15: =[1]ΑΝΤΙΣΤΟΙΧΙΣΗ!F194 | D15: ='[1]2026_ΕΣΟΔΑ'!G9 | E15: =D15/$D$7 | F15: =D15+'[1]2026 Απρίλιος'!F15 | G15: =F15/$F$7 | I15: =H15/$H$7 | J15: =H15+'[1]2026 Απρίλιος'!J15 | K15: =J15/$J$7 | L15: ='[1]2024_60-69 ΕΞΟΔΑ+ΟΜ 2'!G121 | M15: =L15/$L$7 | N15: =L15+'[1]2026 Απρίλιος'!N15 | O15: =N15/$N$7 | P15: =F15-N15 | Q15: =N15/F15
A16: 15 | B16: 9 | C16: =[1]ΑΝΤΙΣΤΟΙΧΙΣΗ!F195 | D16: ='[1]2026_ΕΣΟΔΑ'!G10 | E16: =D16/$D$7 | F16: =D16+'[1]2026 Απρίλιος'!F16 | G16: =F16/$F$7 | I16: =H16/$H$7 | J16: =H16+'[1]2026 Απρίλιος'!J16 | K16: =J16/$J$7 | L16: ='[1]2024_60-69 ΕΞΟΔΑ+ΟΜ 2'!G122 | M16: =L16/$L$7 | N16: =L16+'[1]2026 Απρίλιος'!N16 | O16: =N16/$N$7 | P16: =F16-N16 | Q16: =N16/F16
A17: 16 | B17: 10 | C17: =[1]ΑΝΤΙΣΤΟΙΧΙΣΗ!F196 | D17: ='[1]2026_ΕΣΟΔΑ'!G11 | E17: =D17/$D$7 | F17: =D17+'[1]2026 Απρίλιος'!F17 | G17: =F17/$F$7 | I17: =H17/$H$7 | J17: =H17+'[1]2026 Απρίλιος'!J17 | K17: =J17/$J$7 | L17: ='[1]2024_60-69 ΕΞΟΔΑ+ΟΜ 2'!G123 | M17: =L17/$L$7 | N17: =L17+'[1]2026 Απρίλιος'!N17 | O17: =N17/$N$7 | P17: =F17-N17 | Q17: =N17/F17
A18: 17 | B18: 11 | C18: =[1]ΑΝΤΙΣΤΟΙΧΙΣΗ!F197 | D18: ='[1]2026_ΕΣΟΔΑ'!G12 | E18: =D18/$D$7 | F18: =D18+'[1]2026 Απρίλιος'!F18 | G18: =F18/$F$7 | I18: =H18/$H$7 | J18: =H18+'[1]2026 Απρίλιος'!J18 | K18: =J18/$J$7 | L18: ='[1]2024_60-69 ΕΞΟΔΑ+ΟΜ 2'!G124 | M18: =L18/$L$7 | N18: =L18+'[1]2026 Απρίλιος'!N18 | O18: =N18/$N$7 | P18: =F18-N18 | Q18: =N18/F18
A19: 18 | B19: 12 | C19: =[1]ΑΝΤΙΣΤΟΙΧΙΣΗ!F198 | D19: ='[1]2026_ΕΣΟΔΑ'!G13 | E19: =D19/$D$7 | F19: =D19+'[1]2026 Απρίλιος'!F19 | G19: =F19/$F$7 | I19: =H19/$H$7 | J19: =H19+'[1]2026 Απρίλιος'!J19 | K19: =J19/$J$7 | L19: ='[1]2024_60-69 ΕΞΟΔΑ+ΟΜ 2'!G125 | M19: =L19/$L$7 | N19: =L19+'[1]2026 Απρίλιος'!N19 | O19: =N19/$N$7 | P19: =F19-N19 | Q19: =N19/F19
... A23: 22 | B23: 16 | C23: =[1]ΑΝΤΙΣΤΟΙΧΙΣΗ!F202 | D23: ='[1]2026_ΕΣΟΔΑ'!G17 | E23: =D23/$D$7 | F23: =D23+'[1]2026 Απρίλιος'!F23 | G23: =F23/$F$7 | I23: =H23/$H$7 | J23: =H23+'[1]2026 Απρίλιος'!J23 | K23: =J23/$J$7 | L23: ='[1]2024_60-69 ΕΞΟΔΑ+ΟΜ 2'!G129 | M23: =L23/$L$7 | N23: =L23+'[1]2026 Απρίλιος'!N23 | O23: =N23/$N$7 | P23: =F23-N23 | Q23: =N23/F23
A24: 23 | B24: 17 | C24: =[1]ΑΝΤΙΣΤΟΙΧΙΣΗ!F203 | D24: ='[1]2026_ΕΣΟΔΑ'!G18 | E24: =D24/$D$7 | F24: =D24+'[1]2026 Απρίλιος'!F24 | G24: =F24/$F$7 | H24: =[1]ΠΡΟΥΠΟΛΟΓΙΣΜΟΣ_ΕΣΟΔΑ!E225 | I24: =H24/$H$7 | J24: =H24+'[1]2026 Απρίλιος'!J24 | K24: =J24/$J$7 | L24: ='[1]2024_60-69 ΕΞΟΔΑ+ΟΜ 2'!G130 | M24: =L24/$L$7 | N24: =L24+'[1]2026 Απρίλιος'!N24 | O24: =N24/$N$7 | P24: =F24-N24 | Q24: =N24/F24
A25: 24 | B25: 18 | C25: =[1]ΑΝΤΙΣΤΟΙΧΙΣΗ!F204 | D25: ='[1]2026_ΕΣΟΔΑ'!G19 | E25: =D25/$D$7 | F25: =D25+'[1]2026 Απρίλιος'!F25 | G25: =F25/$F$7 | I25: =H25/$H$7 | J25: =H25+'[1]2026 Απρίλιος'!J25 | K25: =J25/$J$7 | L25: ='[1]2024_60-69 ΕΞΟΔΑ+ΟΜ 2'!G131 | M25: =L25/$L$7 | N25: =L25+'[1]2026 Απρίλιος'!N25 | O25: =N25/$N$7 | P25: =F25-N25 | Q25: =N25/F25
A26: 25 | B26: 19 | C26: =[1]ΑΝΤΙΣΤΟΙΧΙΣΗ!F205 | D26: ='[1]2026_ΕΣΟΔΑ'!G20 | E26: =D26/$D$7 | F26: =D26+'[1]2026 Απρίλιος'!F26 | G26: =F26/$F$7 | I26: =H26/$H$7 | J26: =H26+'[1]2026 Απρίλιος'!J26 | K26: =J26/$J$7 | L26: ='[1]2024_60-69 ΕΞΟΔΑ+ΟΜ 2'!G132 | M26: =L26/$L$7 | N26: =L26+'[1]2026 Απρίλιος'!N26 | O26: =N26/$N$7 | P26: =F26-N26 | Q26: =N26/F26
A27: 26 | B27: 20 | C27: =[1]ΑΝΤΙΣΤΟΙΧΙΣΗ!F206 | D27: ='[1]2026_ΕΣΟΔΑ'!G21 | E27: =D27/$D$7 | F27: =D27+'[1]2026 Απρίλιος'!F27 | G27: =F27/$F$7 | I27: =H27/$H$7 | J27: =H27+'[1]2026 Απρίλιος'!J27 | K27: =J27/$J$7 | L27: ='[1]2024_60-69 ΕΞΟΔΑ+ΟΜ 2'!G133 | M27: =L27/$L$7 | N27: =L27+'[1]2026 Απρίλιος'!N27 | O27: =N27/$N$7 | P27: =F27-N27 | Q27: =N27/F27
A28: 27 | B28: 21 | C28: =[1]ΑΝΤΙΣΤΟΙΧΙΣΗ!F207 | D28: ='[1]2026_ΕΣΟΔΑ'!G22 | E28: =D28/$D$7 | F28: =D28+'[1]2026 Απρίλιος'!F28 | G28: =F28/$F$7 | I28: =H28/$H$7 | J28: =H28+'[1]2026 Απρίλιος'!J28 | K28: =J28/$J$7 | L28: ='[1]2024_60-69 ΕΞΟΔΑ+ΟΜ 2'!G134 | M28: =L28/$L$7 | N28: =L28+'[1]2026 Απρίλιος'!N28 | O28: =N28/$N$7 | P28: =F28-N28 | Q28: =N28/F28
A29: 28 | B29: 22 | C29: =[1]ΑΝΤΙΣΤΟΙΧΙΣΗ!F208 | D29: ='[1]2026_ΕΣΟΔΑ'!G23 | E29: =D29/$D$7 | F29: =D29+'[1]2026 Απρίλιος'!F29 | G29: =F29/$F$7 | I29: =H29/$H$7 | J29: =H29+'[1]2026 Απρίλιος'!J29 | K29: =J29/$J$7 | L29: ='[1]2024_60-69 ΕΞΟΔΑ+ΟΜ 2'!G135 | M29: =L29/$L$7 | N29: =L29+'[1]2026 Απρίλιος'!N29 | O29: =N29/$N$7 | P29: =F29-N29 | Q29: =N29/F29
A30: 29 | B30: 23 | C30: =[1]ΑΝΤΙΣΤΟΙΧΙΣΗ!F209 | D30: ='[1]2026_ΕΣΟΔΑ'!G24 | E30: =D30/$D$7 | F30: =D30+'[1]2026 Απρίλιος'!F30 | G30: =F30/$F$7 | I30: =H30/$H$7 | J30: =H30+'[1]2026 Απρίλιος'!J30 | K30: =J30/$J$7 | L30: ='[1]2024_60-69 ΕΞΟΔΑ+ΟΜ 2'!G136 | M30: =L30/$L$7 | N30: =L30+'[1]2026 Απρίλιος'!N30 | O30: =N30/$N$7 | P30: =F30-N30 | Q30: =N30/F30
A31: 30 | B31: 24 | C31: =[1]ΑΝΤΙΣΤΟΙΧΙΣΗ!F210 | D31: ='[1]2026_ΕΣΟΔΑ'!G25 | E31: =D31/$D$7 | F31: =D31+'[1]2026 Απρίλιος'!F31 | G31: =F31/$F$7 | I31: =H31/$H$7 | J31: =H31+'[1]2026 Απρίλιος'!J31 | K31: =J31/$J$7 | L31: ='[1]2024_60-69 ΕΞΟΔΑ+ΟΜ 2'!G137 | M31: =L31/$L$7 | N31: =L31+'[1]2026 Απρίλιος'!N31 | O31: =N31/$N$7 | P31: =F31-N31 | Q31: =N31/F31
A32: 31 | B32: 25 | C32: =[1]ΑΝΤΙΣΤΟΙΧΙΣΗ!F211 | D32: ='[1]2026_ΕΣΟΔΑ'!G26 | E32: =D32/$D$7 | F32: =D32+'[1]2026 Απρίλιος'!F32 | G32: =F32/$F$7 | I32: =H32/$H$7 | J32: =H32+'[1]2026 Απρίλιος'!J32 | K32: =J32/$J$7 | L32: ='[1]2024_60-69 ΕΞΟΔΑ+ΟΜ 2'!G138 | M32: =L32/$L$7 | N32: =L32+'[1]2026 Απρίλιος'!N32 | O32: =N32/$N$7 | P32: =F32-N32 | Q32: =N32/F32
A33: 32 | B33: 26 | C33: =[1]ΑΝΤΙΣΤΟΙΧΙΣΗ!F212 | D33: ='[1]2026_ΕΣΟΔΑ'!G27 | E33: =D33/$D$7 | F33: =D33+'[1]2026 Απρίλιος'!F33 | G33: =F33/$F$7 | I33: =H33/$H$7 | J33: =H33+'[1]2026 Απρίλιος'!J33 | K33: =J33/$J$7 | L33: ='[1]2024_60-69 ΕΞΟΔΑ+ΟΜ 2'!G139 | M33: =L33/$L$7 | N33: =L33+'[1]2026 Απρίλιος'!N33 | O33: =N33/$N$7 | P33: =F33-N33 | Q33: =N33/F33
A34: 33 | B34: 27 | C34: =[1]ΑΝΤΙΣΤΟΙΧΙΣΗ!F213 | D34: ='[1]2026_ΕΣΟΔΑ'!G28 | E34: =D34/$D$7 | F34: =D34+'[1]2026 Απρίλιος'!F34 | G34: =F34/$F$7 | I34: =H34/$H$7 | J34: =H34+'[1]2026 Απρίλιος'!J34 | K34: =J34/$J$7 | L34: ='[1]2024_60-69 ΕΞΟΔΑ+ΟΜ 2'!G140 | M34: =L34/$L$7 | N34: =L34+'[1]2026 Απρίλιος'!N34 | O34: =N34/$N$7 | P34: =F34-N34 | Q34: =N34/F34
